Workbook

Sheet Cover
A4: Round the clock supply · financial model
A5: 285 MW contracted · 2455 MU a year · 25 years
A6: Prepared 2026-10-24 by Demo · Round the clock (TenderOS)
A7: The key results below are linked to the Live model tab: change an input there (blue cells) and they follow.
A9: Key results
A10: Tariff (₹/kWh) | B10: ='Live model'!$C$9 -> 4.1888732 | C10: Tariff that gives the 14.00% target equity IRR
A11: Equity IRR | B11: ='Live model'!$C$10 -> 0.14
A12: Project IRR | B12: ='Live model'!$C$12 -> 0.09977135
A13: Equity NPV at the target IRR (₹ cr) | B13: ='Live model'!$C$13 -> 2.5618254e-06
A14: Minimum DSCR | B14: ='Live model'!$C$15 -> 1.1034483
A15: Average DSCR | B15: ='Live model'!$C$16 -> 1.5649529
A16: Equity payback (year) | B16: ='Live model'!$C$19 -> 9
A17: Project cost (₹ cr) | B17: ='Live model'!$C$20 -> 4457.25 | C17: ₹15.64 cr per contracted MW
A18: Debt (₹ cr) | B18: ='Live model'!$C$21 -> 3120.075
A19: Equity (₹ cr) | B19: ='Live model'!$C$22 -> 1337.175
A20: Levelised cost of supply (₹/kWh) | B20: ='Live model'!$C$17 -> 3.6350856 | C20: at a 10.0% discount rate
A21: Year-1 supply (MU) | B21: 1645.5381 | C21: 67.0% of demand (target 85.0%)
A22: Lowest DFR over the term | B22: 0.65071641 | C22: below the target in some years
A23: Revenue over 25 years (₹ cr) | B23: ='Live model'!$C$23 -> 16991.469
A25: Plant
A26: Contracted capacity (MW) | B26: 285
A27: Annual energy (MU) | B27: 2455 | C27: load factor 98.3%
A28: Solar (MW) | B28: 450 | C28: 1833 MU generated at the 33 kV bus in year 1 with wind
A29: Wind (MW) | B29: 300
A30: Battery power (MW) | B30: 150
A31: Battery energy (MWh) | B31: 600 | C31: 4.0 h
A33: Key inputs
A34: Supply target | B34: 85.0% of demand, over each year
A35: Losses to the 220 kV meter | B35: transformer 0.40%, line 0.50%, other 0.00%
A36: Capex | B36: solar ₹3.5 cr/MW · wind ₹6.5 cr/MW · battery ₹1.2 cr/MWh · pre-operative 5.0%
A37: Financing | B37: equity IRR 14.0% · debt 70% at 9.00% for 15 years · tax 25.17%
A38: Surplus sale | B38: none
A40: Tender
A42: The plant and its energy come from the Round the clock tab: an hourly simulation of every year of the term, with degradation and battery augmentation.
A43: The Live model tab rebuilds the financial model as Excel formulas on these inputs and energies.

Sheet Live model
A1: Round the clock supply · financial model
A2: Every number below is a formula on the blue inputs and the simulated energy (green). Change a blue cell: the whole model, the returns and the Cover move with it.
A3: Colour key | B3: Input | C3: Simulation | D3: Formula
A4: The energy comes from the Round the clock tab's hourly simulation of every year; changing a plant size here moves its cost, not its energy (change it in the tab for that).
A5: ₹ crore unless stated | B5: Unit | C5: Total / value | D5: Year 0 | E5: 1 | F5: =E5+1 -> 2 | G5: =F5+1 -> 3 | H5: =G5+1 -> 4 | I5: =H5+1 -> 5 | J5: =I5+1 -> 6 | K5: =J5+1 -> 7 | L5: =K5+1 -> 8 | M5: =L5+1 -> 9 | ... AC5: =AB5+1 -> 25
A7: Key results
C8: This workbook | D8: App | E8: Difference | F8: Same as app?
A9: Tariff | B9: ₹/kWh | C9: =$C$29 -> 4.1888732 | D9: 4.1888732 | E9: =IF(ISNUMBER(C9),C9-D9,"") -> 0 | F9: =IF(ISNUMBER(E9),IF(ABS(E9)<=0.000004188873213329757,"Yes","Changed"),"") -> Yes
A10: Equity IRR | B10: % | C10: =IFERROR(IRR(D173:AC173),"n/a") -> 0.14 | D10: 0.14 | E10: =IF(ISNUMBER(C10),C10-D10,"") -> -2.8959107e-10 | F10: =IF(ISNUMBER(E10),IF(ABS(E10)<=0.00001,"Yes","Changed"),"") -> Yes
A11: Equity IRR less the target | B11: % | C11: =IFERROR($C$10-$C$65,"n/a") -> 2.2612875e-10 | D11: 5.1571983e-10 | E11: =IF(ISNUMBER(C11),C11-D11,"") -> -2.8959107e-10 | F11: =IF(ISNUMBER(E11),IF(ABS(E11)<=0.00001,"Yes","Changed"),"") -> Yes
A12: Project IRR | B12: % | C12: =IFERROR(IRR(D177:AC177),"n/a") -> 0.09977135 | D12: 0.09977135 | E12: =IF(ISNUMBER(C12),C12-D12,"") -> 5.9729915e-11 | F12: =IF(ISNUMBER(E12),IF(ABS(E12)<=0.00001,"Yes","Changed"),"") -> Yes
A13: Equity NPV at the target IRR | B13: ₹ cr | C13: =D173+NPV($C$65,E173:AC173) -> 2.5618253e-06 | D13: 2.5618254e-06 | E13: =IF(ISNUMBER(C13),C13-D13,"") -> -1.4210855e-13 | F13: =IF(ISNUMBER(E13),IF(ABS(E13)<=0.000001,"Yes","Changed"),"") -> Yes
A14: Project NPV at the discount rate | B14: ₹ cr | C14: =D177+NPV($C$66,E177:AC177) -> -7.2175463 | D14: -7.2175463 | E14: =IF(ISNUMBER(C14),C14-D14,"") -> -8.9528385e-13 | F14: =IF(ISNUMBER(E14),IF(ABS(E14)<=0.0000072175463088046565,"Yes","Changed"),"") -> Yes
A15: Minimum DSCR | B15: × | C15: =IF(COUNT(E170:AC170)=0,"",MIN(E170:AC170)) -> 1.1034483 | D15: 1.1034483 | E15: =IF(ISNUMBER(C15),C15-D15,"") -> 0 | F15: =IF(ISNUMBER(E15),IF(ABS(E15)<=0.0000011034482724108144,"Yes","Changed"),"") -> Yes
A16: Average DSCR | B16: × | C16: =IF(COUNT(E170:AC170)=0,"",AVERAGE(E170:AC170)) -> 1.5649529 | D16: 1.5649529 | E16: =IF(ISNUMBER(C16),C16-D16,"") -> 0 | F16: =IF(ISNUMBER(E16),IF(ABS(E16)<=0.0000015649528530512658,"Yes","Changed"),"") -> Yes
A17: Levelised cost of supply | B17: ₹/kWh | C17: =IF(C182>0,($C$83+C181)*10/C182,"") -> 3.6350856 | D17: 3.6350856 | E17: =IF(ISNUMBER(C17),C17-D17,"") -> 1.3322676e-15 | F17: =IF(ISNUMBER(E17),IF(ABS(E17)<=0.0000036350856375276427,"Yes","Changed"),"") -> Yes
A18: Levelised tariff | B18: ₹/kWh | C18: =IF(C182>0,C183*10/C182,"") -> 4.1888732 | D18: 4.1888732 | E18: =IF(ISNUMBER(C18),C18-D18,"") -> 8.8817842e-16 | F18: =IF(ISNUMBER(E18),IF(ABS(E18)<=0.000004188873213329756,"Yes","Changed"),"") -> Yes
A19: Equity payback | B19: year | C19: =IF(COUNT(E175:AC175)=0,"beyond the term",MIN(E175:AC175)) -> 9 | D19: 9 | E19: =IF(ISNUMBER(C19),C19-D19,"") -> 0 | F19: =IF(ISNUMBER(E19),IF(ABS(E19)<=0.000009,"Yes","Changed"),"") -> Yes
A20: Project cost | B20: ₹ cr | C20: =$C$83 -> 4457.25 | D20: 4457.25 | E20: =IF(ISNUMBER(C20),C20-D20,"") -> 0 | F20: =IF(ISNUMBER(E20),IF(ABS(E20)<=0.004457249999999999,"Yes","Changed"),"") -> Yes
A21: Debt | B21: ₹ cr | C21: =$C$84 -> 3120.075 | D21: 3120.075 | E21: =IF(ISNUMBER(C21),C21-D21,"") -> 0 | F21: =IF(ISNUMBER(E21),IF(ABS(E21)<=0.0031200749999999995,"Yes","Changed"),"") -> Yes
A22: Equity | B22: ₹ cr | C22: =$C$85 -> 1337.175 | D22: 1337.175 | E22: =IF(ISNUMBER(C22),C22-D22,"") -> 0 | F22: =IF(ISNUMBER(E22),IF(ABS(E22)<=0.0013371750000000001,"Yes","Changed"),"") -> Yes
A23: Revenue over 25 years | B23: ₹ cr | C23: =C118 -> 16991.469 | D23: 16991.469 | E23: =IF(ISNUMBER(C23),C23-D23,"") -> 0 | F23: =IF(ISNUMBER(E23),IF(ABS(E23)<=0.016991469492670403,"Yes","Changed"),"") -> Yes
A24: Model checks | C24: =IF(AND($C$197="OK",$C$198="OK",$C$199="OK",$C$200="OK"),"OK","CHECK") -> OK | F24: =IF(C24="OK","OK","CHECK") -> OK
A25: To price the supply again after changing an input: Data › What-If Analysis › Goal Seek, set the cell "Equity IRR less the target" to 0 by changing the tariff.
A27: Inputs
A28: Tariff
A29: Tariff | B29: ₹/kWh | C29: 4.1888732 | D29: Solved in TenderOS for the target equity IRR
A30: Tariff escalation | B30: %/yr | C30: 0 | D30: Round the clock tab
A31: Plant (from the Round the clock tab)
A32: Solar | B32: MW | C32: 450 | D32: Round the clock plant
A33: Wind | B33: MW | C33: 300 | D33: Round the clock plant
A34: Battery power | B34: MW | C34: 150 | D34: Round the clock plant
A35: Battery energy | B35: MWh | C35: 600 | D35: Round the clock plant
A36: Capital cost
A37: Solar | B37: ₹ cr/MW | C37: 3.5 | D37: Round the clock tab
A38: Wind | B38: ₹ cr/MW | C38: 6.5 | D38: Round the clock tab
A39: Battery energy | B39: ₹ cr/MWh | C39: 1.2 | D39: Round the clock tab
A40: Battery power conversion | B40: ₹ cr/MW | C40: 0 | D40: Round the clock tab
A41: Transmission / evacuation | B41: ₹ cr | C41: 0 | D41: Round the clock tab
A42: Pre-operative and IDC | B42: % of hard cost | C42: 0.05 | D42: Round the clock tab
...

Sheet Inputs
A1: Group | B1: Input | C1: Value | D1: Unit | E1: Source
A2: Demand | B2: Annual energy | C2: 2455 | D2: MU | E2: Round the clock tab
A3: Demand | B3: Contracted capacity | C3: 285 | D3: MW | E3: Round the clock tab
A4: Demand | B4: Supply target (DFR) | C4: 0.85 | D4: % | E4: Round the clock tab
A5: Demand | B5: Target basis | C5: annual | E5: Round the clock tab
A6: Demand | B6: Design check | C6: lifetime | E6: Round the clock tab
A7: Demand | B7: Demand growth | C7: 0 | D7: % | E7: Round the clock tab
A8: Losses | B8: Other losses before the 33 kV bus | C8: 0 | D8: % | E8: Round the clock tab
A9: Losses | B9: Power transformer 33/220 kV | C9: 0.004 | D9: % | E9: Round the clock tab
A10: Losses | B10: 220 kV line to the GSS | C10: 0.005 | D10: % | E10: Round the clock tab
A11: Plant | B11: Solar | C11: 450 | D11: MW | E11: Round the clock tab
A12: Plant | B12: Wind | C12: 300 | D12: MW | E12: Round the clock tab
A13: Plant | B13: Battery power | C13: 150 | D13: MW | E13: Round the clock tab
A14: Plant | B14: Battery energy | C14: 600 | D14: MWh | E14: Round the clock tab
A15: Battery | B15: Round-trip efficiency at the 33 kV bus | C15: 0.87 | D15: % | E15: Round the clock tab
A16: Battery | B16: Capacity fade | C16: 0.02 | D16: % | E16: Round the clock tab
A17: Battery | B17: Augmentation | C17: annual | E17: Round the clock tab
A18: Battery | B18: One-time augmentation year | C18: 12 | D18: year | E18: Round the clock tab
A19: Battery | B19: Battery price decline | C19: 0.03 | D19: % | E19: Round the clock tab
A20: Capex | B20: Solar | C20: 3.5 | D20: ₹ cr/MW | E20: Round the clock tab
A21: Capex | B21: Wind | C21: 6.5 | D21: ₹ cr/MW | E21: Round the clock tab
A22: Capex | B22: Battery energy | C22: 1.2 | D22: ₹ cr/MWh | E22: Round the clock tab
A23: Capex | B23: Battery power conversion | C23: 0 | D23: ₹ cr/MW | E23: Round the clock tab
A24: Capex | B24: Evacuation | C24: 0 | D24: ₹ cr | E24: Round the clock tab
A25: Capex | B25: Pre-operative and IDC | C25: 0.05 | D25: % | E25: Round the clock tab
A26: Operation and finance | B26: Solar O&M | C26: 4 | D26: ₹ lakh/MW/yr | E26: Round the clock tab
A27: Operation and finance | B27: Wind O&M | C27: 9 | D27: ₹ lakh/MW/yr | E27: Round the clock tab
A28: Operation and finance | B28: Battery O&M | C28: 1.2 | D28: ₹ lakh/MWh/yr | E28: Round the clock tab
A29: Operation and finance | B29: O&M escalation | C29: 0.05 | D29: % | E29: Round the clock tab
... A40: Operation and finance | B40: Loan tenor | C40: 15 | D40: years | E40: Round the clock tab
A41: Operation and finance | B41: Repayment | C41: equal | E41: Round the clock tab
A42: Operation and finance | B42: Corporate tax | C42: 0.2517 | D42: % | E42: Round the clock tab
A43: Operation and finance | B43: Tax depreciation | C43: wdv | E43: Round the clock tab
A44: Operation and finance | B44: WDV rate | C44: 0.4 | D44: % | E44: Round the clock tab
A45: Operation and finance | B45: Book life | C45: 25 | D45: years | E45: Round the clock tab
A46: Operation and finance | B46: Salvage value | C46: 0.1 | D46: % | E46: Round the clock tab
A47: Operation and finance | B47: Receivable days | C47: 45 | D47: days | E47: Round the clock tab
A48: Operation and finance | B48: Discount rate | C48: 0.1 | D48: % | E48: Round the clock tab
A49: Operation and finance | B49: Sell surplus | C49: No | E49: Round the clock tab

Sheet Plant and capex
A1: Item | B1: Value | C1: Note
A2: Contracted capacity (MW) | B2: 285
A3: Annual energy (MU) | B3: 2455 | C3: load factor 98.3%
A4: Solar (MW) | B4: 450 | C4: 1833 MU generated at the 33 kV bus in year 1 with wind
A5: Wind (MW) | B5: 300
A6: Battery power (MW) | B6: 150
A7: Battery energy (MWh) | B7: 600 | C7: 4.0 h
A9: Capex | B9: ₹ crore | C9: Note
A10: Solar | B10: 1653.75
A11: Wind | B11: 2047.5
A12: Battery energy | B12: 756
A13: Transmission / evacuation | B13: 0
A14: Total project cost (incl. pre-operative & IDC) | B14: 4457.25 | C14: pre-operative 5.0% of hard cost
A15: Debt | B15: 3120.075 | C15: 70%
A16: Equity | B16: 1337.175

Sheet Revenue and costs (values)
A1: ₹ crore unless stated | B1: Unit | C1: Total | D1: Year 1 | E1: Year 2 | F1: Year 3 | G1: Year 4 | H1: Year 5 | I1: Year 6 | J1: Year 7 | K1: Year 8 | L1: Year 9 | M1: Year 10 | N1: Year 11 | O1: Year 12 | P1: Year 13 | Q1: Year 14 | R1: Year 15 | S1: Year 16 | T1: Year 17 | U1: Year 18 | V1: Year 19 | W1: Year 20 | X1: Year 21 | Y1: Year 22 | Z1: Year 23 | AA1: Year 24 | AB1: Year 25
A2: Energy and tariff
A3: Demand | B3: MU | C3: 61375 | D3: 2455 | E3: 2455 | F3: 2455 | G3: 2455 | H3: 2455 | I3: 2455 | J3: 2455 | K3: 2455 | L3: 2455 | M3: 2455 | N3: 2455 | O3: 2455 | P3: 2455 | Q3: 2455 | R3: 2455 | S3: 2455 | T3: 2455 | U3: 2455 | V3: 2455 | W3: 2455 | X3: 2455 | Y3: 2455 | Z3: 2455 | AA3: 2455 | AB3: 2455
A4: Generated at the 33 kV bus | B4: MU | C4: 44431.102 | D4: 1833.03 | E4: 1828.201 | F4: 1823.3962 | G4: 1818.6155 | H4: 1813.8586 | I4: 1809.1255 | J4: 1804.4161 | K4: 1799.7302 | L4: 1795.0677 | M4: 1790.4286 | N4: 1785.8127 | O4: 1781.2198 | P4: 1776.6499 | Q4: 1772.1028 | R4: 1767.5785 | S4: 1763.0768 | T4: 1758.5977 | U4: 1754.1409 | V4: 1749.7064 | W4: 1745.294 | X4: 1740.9038 | Y4: 1736.5354 | Z4: 1732.189 | AA4: 1727.8642 | AB4: 1723.5611
A5: Injected at the 33 kV bus | B5: MU | C5: 40930.901 | D5: 1660.449 | E5: 1658.7384 | F5: 1656.9683 | G5: 1655.1505 | H5: 1653.3126 | I5: 1651.4539 | J5: 1649.5735 | K5: 1647.6743 | L5: 1645.7502 | M5: 1643.8251 | N5: 1641.8661 | O5: 1639.8678 | P5: 1637.8506 | Q5: 1635.8238 | R5: 1633.7583 | S5: 1631.6486 | T5: 1629.5071 | U5: 1627.3539 | V5: 1625.2079 | W5: 1623.0377 | X5: 1620.8441 | Y5: 1618.6334 | Z5: 1616.4175 | AA5: 1614.2043 | AB5: 1611.9844
A6: Power transformer loss | B6: MU | C6: 163.7236 | D6: 6.6417959 | E6: 6.6349535 | F6: 6.627873 | G6: 6.6206018 | H6: 6.6132505 | I6: 6.6058157 | J6: 6.5982939 | K6: 6.5906971 | L6: 6.5830006 | M6: 6.5753004 | N6: 6.5674645 | O6: 6.5594712 | P6: 6.5514022 | Q6: 6.5432952 | R6: 6.5350331 | S6: 6.5265945 | T6: 6.5180284 | U6: 6.5094156 | V6: 6.5008315 | W6: 6.4921509 | X6: 6.4833765 | Y6: 6.4745335 | Z6: 6.4656699 | AA6: 6.4568171 | AB6: 6.4479376
A7: Transmission line loss | B7: MU | C7: 203.83589 | D7: 8.2690359 | E7: 8.2605171 | F7: 8.2517019 | G7: 8.2426493 | H7: 8.2334969 | I7: 8.2242406 | J7: 8.2148759 | K7: 8.2054179 | L7: 8.1958358 | M7: 8.186249 | N7: 8.1764933 | O7: 8.1665417 | P7: 8.1564958 | Q7: 8.1464025 | R7: 8.1361162 | S7: 8.1256102 | T7: 8.1149453 | U7: 8.1042224 | V7: 8.0935353 | W7: 8.0827279 | X7: 8.0718038 | Y7: 8.0607943 | Z7: 8.049759 | AA7: 8.0387373 | AB7: 8.0276823
A8: At the 220 kV billing meter | B8: MU | C8: 40563.342 | D8: 1645.5381 | E8: 1643.8429 | F8: 1642.0887 | G8: 1640.2872 | H8: 1638.4659 | I8: 1636.6239 | J8: 1634.7603 | K8: 1632.8782 | L8: 1630.9713 | M8: 1629.0635 | N8: 1627.1222 | O8: 1625.1418 | P8: 1623.1427 | Q8: 1621.1341 | R8: 1619.0871 | S8: 1616.9964 | T8: 1614.8741 | U8: 1612.7403 | V8: 1610.6135 | W8: 1608.4628 | X8: 1606.289 | Y8: 1604.0981 | Z8: 1601.902 | AA8: 1599.7087 | AB8: 1597.5088
A9: Delivered to the customer | B9: MU | C9: 40563.342 | D9: 1645.5381 | E9: 1643.8429 | F9: 1642.0887 | G9: 1640.2872 | H9: 1638.4659 | I9: 1636.6239 | J9: 1634.7603 | K9: 1632.8782 | L9: 1630.9713 | M9: 1629.0635 | N9: 1627.1222 | O9: 1625.1418 | P9: 1623.1427 | Q9: 1621.1341 | R9: 1619.0871 | S9: 1616.9964 | T9: 1614.8741 | U9: 1612.7403 | V9: 1610.6135 | W9: 1608.4628 | X9: 1606.289 | Y9: 1604.0981 | Z9: 1601.902 | AA9: 1599.7087 | AB9: 1597.5088
A10: DFR (delivered ÷ demand) | D10: 0.6702803 | E10: 0.66958978 | F10: 0.66887523 | G10: 0.66814143 | H10: 0.66739954 | I10: 0.66664924 | J10: 0.66589014 | K10: 0.66512349 | L10: 0.66434677 | M10: 0.66356967 | N10: 0.66277889 | O10: 0.66197222 | P10: 0.66115791 | Q10: 0.66033975 | R10: 0.65950596 | S10: 0.65865435 | T10: 0.65778986 | U10: 0.65692067 | V10: 0.65605439 | W10: 0.65517835 | X10: 0.65429285 | Y10: 0.65340043 | Z10: 0.65250592 | AA10: 0.65161252 | AB10: 0.65071641
A11: Surplus sold | B11: MU | C11: 0 | D11: 0 | E11: 0 | F11: 0 | G11: 0 | H11: 0 | I11: 0 | J11: 0 | K11: 0 | L11: 0 | M11: 0 | N11: 0 | O11: 0 | P11: 0 | Q11: 0 | R11: 0 | S11: 0 | T11: 0 | U11: 0 | V11: 0 | W11: 0 | X11: 0 | Y11: 0 | Z11: 0 | AA11: 0 | AB11: 0
A12: Curtailed | B12: MU | C12: 2993.5585 | D12: 150.65069 | E12: 147.64332 | F12: 144.72763 | G12: 141.89026 | H12: 139.09915 | I12: 136.35569 | J12: 133.66039 | K12: 131.00853 | L12: 128.40812 | M12: 125.83124 | N12: 123.31585 | O12: 120.86838 | P12: 118.4645 | Q12: 116.09354 | R12: 113.78887 | S12: 111.55604 | T12: 109.38202 | U12: 107.24275 | V12: 105.11649 | W12: 103.03959 | X12: 101.01052 | Y12: 99.022648 | Z12: 97.061732 | AA12: 95.118334 | AB12: 93.202205
A13: Shortfall vs target | B13: MU | C13: 11605.408 | D13: 441.21186 | E13: 442.9071 | F13: 444.66132 | G13: 446.4628 | H13: 448.28412 | I13: 450.12613 | J13: 451.9897 | K13: 453.87184 | L13: 455.77868 | M13: 457.68646 | N13: 459.62783 | O13: 461.6082 | P13: 463.60734 | Q13: 465.61591 | R13: 467.66287 | S13: 469.75358 | T13: 471.87588 | U13: 474.00975 | V13: 476.13648 | W13: 478.28716 | X13: 480.46105 | Y13: 482.65194 | Z13: 484.84796 | AA13: 487.04127 | AB13: 489.24122
A14: Tariff | B14: ₹/kWh | D14: 4.1888732 | E14: 4.1888732 | F14: 4.1888732 | G14: 4.1888732 | H14: 4.1888732 | I14: 4.1888732 | J14: 4.1888732 | K14: 4.1888732 | L14: 4.1888732 | M14: 4.1888732 | N14: 4.1888732 | O14: 4.1888732 | P14: 4.1888732 | Q14: 4.1888732 | R14: 4.1888732 | S14: 4.1888732 | T14: 4.1888732 | U14: 4.1888732 | V14: 4.1888732 | W14: 4.1888732 | X14: 4.1888732 | Y14: 4.1888732 | Z14: 4.1888732 | AA14: 4.1888732 | AB14: 4.1888732
A15: Revenue
A16: Energy revenue | C16: 16991.469 | D16: 689.29506 | E16: 688.58495 | F16: 687.85013 | G16: 687.09551 | H16: 686.33258 | I16: 685.56099 | J16: 684.78036 | K16: 683.99196 | L16: 683.19321 | M16: 682.39406 | N16: 681.58085 | O16: 680.7513 | P16: 679.91388 | Q16: 679.07252 | R16: 678.21507 | S16: 677.3393 | T16: 676.45029 | U16: 675.55644 | V16: 674.66558 | W16: 673.76469 | X16: 672.85408 | Y16: 671.93634 | Z16: 671.01646 | AA16: 670.09771 | AB16: 669.17617
A17: Surplus sale revenue | C17: 0 | D17: 0 | E17: 0 | F17: 0 | G17: 0 | H17: 0 | I17: 0 | J17: 0 | K17: 0 | L17: 0 | M17: 0 | N17: 0 | O17: 0 | P17: 0 | Q17: 0 | R17: 0 | S17: 0 | T17: 0 | U17: 0 | V17: 0 | W17: 0 | X17: 0 | Y17: 0 | Z17: 0 | AA17: 0 | AB17: 0
A18: Shortfall penalty | C18: 0 | D18: 0 | E18: 0 | F18: 0 | G18: 0 | H18: 0 | I18: 0 | J18: 0 | K18: 0 | L18: 0 | M18: 0 | N18: 0 | O18: 0 | P18: 0 | Q18: 0 | R18: 0 | S18: 0 | T18: 0 | U18: 0 | V18: 0 | W18: 0 | X18: 0 | Y18: 0 | Z18: 0 | AA18: 0 | AB18: 0
A19: Total revenue | C19: 16991.469 | D19: 689.29506 | E19: 688.58495 | F19: 687.85013 | G19: 687.09551 | H19: 686.33258 | I19: 685.56099 | J19: 684.78036 | K19: 683.99196 | L19: 683.19321 | M19: 682.39406 | N19: 681.58085 | O19: 680.7513 | P19: 679.91388 | Q19: 679.07252 | R19: 678.21507 | S19: 677.3393 | T19: 676.45029 | U19: 675.55644 | V19: 674.66558 | W19: 673.76469 | X19: 672.85408 | Y19: 671.93634 | Z19: 671.01646 | AA19: 670.09771 | AB19: 669.17617
A20: Operating costs
A21: O&M | C21: 2491.3546 | D21: 52.2 | E21: 54.81 | F21: 57.5505 | G21: 60.428025 | H21: 63.449426 | I21: 66.621898 | J21: 69.952992 | K21: 73.450642 | L21: 77.123174 | M21: 80.979333 | N21: 85.0283 | O21: 89.279714 | P21: 93.7437 | Q21: 98.430885 | R21: 103.35243 | S21: 108.52005 | T21: 113.94605 | U21: 119.64336 | V21: 125.62552 | W21: 131.9068 | X21: 138.50214 | Y21: 145.42725 | Z21: 152.69861 | AA21: 160.33354 | AB21: 168.35022
A22: Insurance | C22: 318.375 | D22: 12.735 | E22: 12.735 | F22: 12.735 | G22: 12.735 | H22: 12.735 | I22: 12.735 | J22: 12.735 | K22: 12.735 | L22: 12.735 | M22: 12.735 | N22: 12.735 | O22: 12.735 | P22: 12.735 | Q22: 12.735 | R22: 12.735 | S22: 12.735 | T22: 12.735 | U22: 12.735 | V22: 12.735 | W22: 12.735 | X22: 12.735 | Y22: 12.735 | Z22: 12.735 | AA22: 12.735 | AB22: 12.735
A23: Other fixed cost | C23: 0 | D23: 0 | E23: 0 | F23: 0 | G23: 0 | H23: 0 | I23: 0 | J23: 0 | K23: 0 | L23: 0 | M23: 0 | N23: 0 | O23: 0 | P23: 0 | Q23: 0 | R23: 0 | S23: 0 | T23: 0 | U23: 0 | V23: 0 | W23: 0 | X23: 0 | Y23: 0 | Z23: 0 | AA23: 0 | AB23: 0
A24: Total operating cost | C24: 2809.7296 | D24: 64.935 | E24: 67.545 | F24: 70.2855 | G24: 73.163025 | H24: 76.184426 | I24: 79.356898 | J24: 82.687992 | K24: 86.185642 | L24: 89.858174 | M24: 93.714333 | N24: 97.7633 | O24: 102.01471 | P24: 106.4787 | Q24: 111.16589 | R24: 116.08743 | S24: 121.25505 | T24: 126.68105 | U24: 132.37836 | V24: 138.36052 | W24: 144.6418 | X24: 151.23714 | Y24: 158.16225 | Z24: 165.43361 | AA24: 173.06854 | AB24: 181.08522
A25: Capital spend in operation
A26: Battery augmentation | C26: 241.45214 | D26: 0 | E26: 13.968 | F26: 13.54896 | G26: 13.142491 | H26: 12.748216 | I26: 12.36577 | J26: 11.994797 | K26: 11.634953 | L26: 11.285904 | M26: 10.947327 | N26: 10.618907 | O26: 10.30034 | P26: 9.99133 | Q26: 9.6915901 | R26: 9.4008424 | S26: 9.1188171 | T26: 8.8452526 | U26: 8.579895 | V26: 8.3224982 | W26: 8.0728232 | X26: 7.8306385 | Y26: 7.5957194 | Z26: 7.3678478 | AA26: 7.1468124 | AB26: 6.932408

Sheet Financial model (values)
A1: ₹ crore unless stated | B1: Unit | C1: Total | D1: Year 1 | E1: Year 2 | F1: Year 3 | G1: Year 4 | H1: Year 5 | I1: Year 6 | J1: Year 7 | K1: Year 8 | L1: Year 9 | M1: Year 10 | N1: Year 11 | O1: Year 12 | P1: Year 13 | Q1: Year 14 | R1: Year 15 | S1: Year 16 | T1: Year 17 | U1: Year 18 | V1: Year 19 | W1: Year 20 | X1: Year 21 | Y1: Year 22 | Z1: Year 23 | AA1: Year 24 | AB1: Year 25
A2: Energy and tariff
A3: Demand | B3: MU | C3: 61375 | D3: 2455 | E3: 2455 | F3: 2455 | G3: 2455 | H3: 2455 | I3: 2455 | J3: 2455 | K3: 2455 | L3: 2455 | M3: 2455 | N3: 2455 | O3: 2455 | P3: 2455 | Q3: 2455 | R3: 2455 | S3: 2455 | T3: 2455 | U3: 2455 | V3: 2455 | W3: 2455 | X3: 2455 | Y3: 2455 | Z3: 2455 | AA3: 2455 | AB3: 2455
A4: Generated at the 33 kV bus | B4: MU | C4: 44431.102 | D4: 1833.03 | E4: 1828.201 | F4: 1823.3962 | G4: 1818.6155 | H4: 1813.8586 | I4: 1809.1255 | J4: 1804.4161 | K4: 1799.7302 | L4: 1795.0677 | M4: 1790.4286 | N4: 1785.8127 | O4: 1781.2198 | P4: 1776.6499 | Q4: 1772.1028 | R4: 1767.5785 | S4: 1763.0768 | T4: 1758.5977 | U4: 1754.1409 | V4: 1749.7064 | W4: 1745.294 | X4: 1740.9038 | Y4: 1736.5354 | Z4: 1732.189 | AA4: 1727.8642 | AB4: 1723.5611
A5: Injected at the 33 kV bus | B5: MU | C5: 40930.901 | D5: 1660.449 | E5: 1658.7384 | F5: 1656.9683 | G5: 1655.1505 | H5: 1653.3126 | I5: 1651.4539 | J5: 1649.5735 | K5: 1647.6743 | L5: 1645.7502 | M5: 1643.8251 | N5: 1641.8661 | O5: 1639.8678 | P5: 1637.8506 | Q5: 1635.8238 | R5: 1633.7583 | S5: 1631.6486 | T5: 1629.5071 | U5: 1627.3539 | V5: 1625.2079 | W5: 1623.0377 | X5: 1620.8441 | Y5: 1618.6334 | Z5: 1616.4175 | AA5: 1614.2043 | AB5: 1611.9844
A6: Power transformer loss | B6: MU | C6: 163.7236 | D6: 6.6417959 | E6: 6.6349535 | F6: 6.627873 | G6: 6.6206018 | H6: 6.6132505 | I6: 6.6058157 | J6: 6.5982939 | K6: 6.5906971 | L6: 6.5830006 | M6: 6.5753004 | N6: 6.5674645 | O6: 6.5594712 | P6: 6.5514022 | Q6: 6.5432952 | R6: 6.5350331 | S6: 6.5265945 | T6: 6.5180284 | U6: 6.5094156 | V6: 6.5008315 | W6: 6.4921509 | X6: 6.4833765 | Y6: 6.4745335 | Z6: 6.4656699 | AA6: 6.4568171 | AB6: 6.4479376
A7: Transmission line loss | B7: MU | C7: 203.83589 | D7: 8.2690359 | E7: 8.2605171 | F7: 8.2517019 | G7: 8.2426493 | H7: 8.2334969 | I7: 8.2242406 | J7: 8.2148759 | K7: 8.2054179 | L7: 8.1958358 | M7: 8.186249 | N7: 8.1764933 | O7: 8.1665417 | P7: 8.1564958 | Q7: 8.1464025 | R7: 8.1361162 | S7: 8.1256102 | T7: 8.1149453 | U7: 8.1042224 | V7: 8.0935353 | W7: 8.0827279 | X7: 8.0718038 | Y7: 8.0607943 | Z7: 8.049759 | AA7: 8.0387373 | AB7: 8.0276823
A8: At the 220 kV billing meter | B8: MU | C8: 40563.342 | D8: 1645.5381 | E8: 1643.8429 | F8: 1642.0887 | G8: 1640.2872 | H8: 1638.4659 | I8: 1636.6239 | J8: 1634.7603 | K8: 1632.8782 | L8: 1630.9713 | M8: 1629.0635 | N8: 1627.1222 | O8: 1625.1418 | P8: 1623.1427 | Q8: 1621.1341 | R8: 1619.0871 | S8: 1616.9964 | T8: 1614.8741 | U8: 1612.7403 | V8: 1610.6135 | W8: 1608.4628 | X8: 1606.289 | Y8: 1604.0981 | Z8: 1601.902 | AA8: 1599.7087 | AB8: 1597.5088
A9: Delivered to the customer | B9: MU | C9: 40563.342 | D9: 1645.5381 | E9: 1643.8429 | F9: 1642.0887 | G9: 1640.2872 | H9: 1638.4659 | I9: 1636.6239 | J9: 1634.7603 | K9: 1632.8782 | L9: 1630.9713 | M9: 1629.0635 | N9: 1627.1222 | O9: 1625.1418 | P9: 1623.1427 | Q9: 1621.1341 | R9: 1619.0871 | S9: 1616.9964 | T9: 1614.8741 | U9: 1612.7403 | V9: 1610.6135 | W9: 1608.4628 | X9: 1606.289 | Y9: 1604.0981 | Z9: 1601.902 | AA9: 1599.7087 | AB9: 1597.5088
A10: DFR (delivered ÷ demand) | D10: 0.6702803 | E10: 0.66958978 | F10: 0.66887523 | G10: 0.66814143 | H10: 0.66739954 | I10: 0.66664924 | J10: 0.66589014 | K10: 0.66512349 | L10: 0.66434677 | M10: 0.66356967 | N10: 0.66277889 | O10: 0.66197222 | P10: 0.66115791 | Q10: 0.66033975 | R10: 0.65950596 | S10: 0.65865435 | T10: 0.65778986 | U10: 0.65692067 | V10: 0.65605439 | W10: 0.65517835 | X10: 0.65429285 | Y10: 0.65340043 | Z10: 0.65250592 | AA10: 0.65161252 | AB10: 0.65071641
A11: Surplus sold | B11: MU | C11: 0 | D11: 0 | E11: 0 | F11: 0 | G11: 0 | H11: 0 | I11: 0 | J11: 0 | K11: 0 | L11: 0 | M11: 0 | N11: 0 | O11: 0 | P11: 0 | Q11: 0 | R11: 0 | S11: 0 | T11: 0 | U11: 0 | V11: 0 | W11: 0 | X11: 0 | Y11: 0 | Z11: 0 | AA11: 0 | AB11: 0
A12: Curtailed | B12: MU | C12: 2993.5585 | D12: 150.65069 | E12: 147.64332 | F12: 144.72763 | G12: 141.89026 | H12: 139.09915 | I12: 136.35569 | J12: 133.66039 | K12: 131.00853 | L12: 128.40812 | M12: 125.83124 | N12: 123.31585 | O12: 120.86838 | P12: 118.4645 | Q12: 116.09354 | R12: 113.78887 | S12: 111.55604 | T12: 109.38202 | U12: 107.24275 | V12: 105.11649 | W12: 103.03959 | X12: 101.01052 | Y12: 99.022648 | Z12: 97.061732 | AA12: 95.118334 | AB12: 93.202205
A13: Shortfall vs target | B13: MU | C13: 11605.408 | D13: 441.21186 | E13: 442.9071 | F13: 444.66132 | G13: 446.4628 | H13: 448.28412 | I13: 450.12613 | J13: 451.9897 | K13: 453.87184 | L13: 455.77868 | M13: 457.68646 | N13: 459.62783 | O13: 461.6082 | P13: 463.60734 | Q13: 465.61591 | R13: 467.66287 | S13: 469.75358 | T13: 471.87588 | U13: 474.00975 | V13: 476.13648 | W13: 478.28716 | X13: 480.46105 | Y13: 482.65194 | Z13: 484.84796 | AA13: 487.04127 | AB13: 489.24122
A14: Tariff | B14: ₹/kWh | D14: 4.1888732 | E14: 4.1888732 | F14: 4.1888732 | G14: 4.1888732 | H14: 4.1888732 | I14: 4.1888732 | J14: 4.1888732 | K14: 4.1888732 | L14: 4.1888732 | M14: 4.1888732 | N14: 4.1888732 | O14: 4.1888732 | P14: 4.1888732 | Q14: 4.1888732 | R14: 4.1888732 | S14: 4.1888732 | T14: 4.1888732 | U14: 4.1888732 | V14: 4.1888732 | W14: 4.1888732 | X14: 4.1888732 | Y14: 4.1888732 | Z14: 4.1888732 | AA14: 4.1888732 | AB14: 4.1888732
A15: Revenue
A16: Energy revenue | C16: 16991.469 | D16: 689.29506 | E16: 688.58495 | F16: 687.85013 | G16: 687.09551 | H16: 686.33258 | I16: 685.56099 | J16: 684.78036 | K16: 683.99196 | L16: 683.19321 | M16: 682.39406 | N16: 681.58085 | O16: 680.7513 | P16: 679.91388 | Q16: 679.07252 | R16: 678.21507 | S16: 677.3393 | T16: 676.45029 | U16: 675.55644 | V16: 674.66558 | W16: 673.76469 | X16: 672.85408 | Y16: 671.93634 | Z16: 671.01646 | AA16: 670.09771 | AB16: 669.17617
A17: Surplus sale revenue | C17: 0 | D17: 0 | E17: 0 | F17: 0 | G17: 0 | H17: 0 | I17: 0 | J17: 0 | K17: 0 | L17: 0 | M17: 0 | N17: 0 | O17: 0 | P17: 0 | Q17: 0 | R17: 0 | S17: 0 | T17: 0 | U17: 0 | V17: 0 | W17: 0 | X17: 0 | Y17: 0 | Z17: 0 | AA17: 0 | AB17: 0
A18: Shortfall penalty | C18: 0 | D18: 0 | E18: 0 | F18: 0 | G18: 0 | H18: 0 | I18: 0 | J18: 0 | K18: 0 | L18: 0 | M18: 0 | N18: 0 | O18: 0 | P18: 0 | Q18: 0 | R18: 0 | S18: 0 | T18: 0 | U18: 0 | V18: 0 | W18: 0 | X18: 0 | Y18: 0 | Z18: 0 | AA18: 0 | AB18: 0
A19: Total revenue | C19: 16991.469 | D19: 689.29506 | E19: 688.58495 | F19: 687.85013 | G19: 687.09551 | H19: 686.33258 | I19: 685.56099 | J19: 684.78036 | K19: 683.99196 | L19: 683.19321 | M19: 682.39406 | N19: 681.58085 | O19: 680.7513 | P19: 679.91388 | Q19: 679.07252 | R19: 678.21507 | S19: 677.3393 | T19: 676.45029 | U19: 675.55644 | V19: 674.66558 | W19: 673.76469 | X19: 672.85408 | Y19: 671.93634 | Z19: 671.01646 | AA19: 670.09771 | AB19: 669.17617
A20: Operating costs
A21: O&M | C21: 2491.3546 | D21: 52.2 | E21: 54.81 | F21: 57.5505 | G21: 60.428025 | H21: 63.449426 | I21: 66.621898 | J21: 69.952992 | K21: 73.450642 | L21: 77.123174 | M21: 80.979333 | N21: 85.0283 | O21: 89.279714 | P21: 93.7437 | Q21: 98.430885 | R21: 103.35243 | S21: 108.52005 | T21: 113.94605 | U21: 119.64336 | V21: 125.62552 | W21: 131.9068 | X21: 138.50214 | Y21: 145.42725 | Z21: 152.69861 | AA21: 160.33354 | AB21: 168.35022
A22: Insurance | C22: 318.375 | D22: 12.735 | E22: 12.735 | F22: 12.735 | G22: 12.735 | H22: 12.735 | I22: 12.735 | J22: 12.735 | K22: 12.735 | L22: 12.735 | M22: 12.735 | N22: 12.735 | O22: 12.735 | P22: 12.735 | Q22: 12.735 | R22: 12.735 | S22: 12.735 | T22: 12.735 | U22: 12.735 | V22: 12.735 | W22: 12.735 | X22: 12.735 | Y22: 12.735 | Z22: 12.735 | AA22: 12.735 | AB22: 12.735
A23: Other fixed cost | C23: 0 | D23: 0 | E23: 0 | F23: 0 | G23: 0 | H23: 0 | I23: 0 | J23: 0 | K23: 0 | L23: 0 | M23: 0 | N23: 0 | O23: 0 | P23: 0 | Q23: 0 | R23: 0 | S23: 0 | T23: 0 | U23: 0 | V23: 0 | W23: 0 | X23: 0 | Y23: 0 | Z23: 0 | AA23: 0 | AB23: 0
A24: Total operating cost | C24: 2809.7296 | D24: 64.935 | E24: 67.545 | F24: 70.2855 | G24: 73.163025 | H24: 76.184426 | I24: 79.356898 | J24: 82.687992 | K24: 86.185642 | L24: 89.858174 | M24: 93.714333 | N24: 97.7633 | O24: 102.01471 | P24: 106.4787 | Q24: 111.16589 | R24: 116.08743 | S24: 121.25505 | T24: 126.68105 | U24: 132.37836 | V24: 138.36052 | W24: 144.6418 | X24: 151.23714 | Y24: 158.16225 | Z24: 165.43361 | AA24: 173.06854 | AB24: 181.08522
A25: Profit and loss
A26: EBITDA | C26: 14181.74 | D26: 624.36006 | E26: 621.03995 | F26: 617.56463 | G26: 613.93249 | H26: 610.14816 | I26: 606.20409 | J26: 602.09237 | K26: 597.80632 | L26: 593.33503 | M26: 588.67973 | N26: 583.81755 | O26: 578.73658 | P26: 573.43518 | Q26: 567.90663 | R26: 562.12764 | S26: 556.08425 | T26: 549.76924 | U26: 543.17809 | V26: 536.30506 | W26: 529.12289 | X26: 521.61694 | Y26: 513.77409 | Z26: 505.58285 | AA26: 497.02917 | AB26: 488.09096
A27: Book depreciation | C27: 4252.9771 | D27: 160.461 | E27: 161.043 | F27: 161.63209 | G27: 162.22947 | H27: 162.83653 | I27: 163.45482 | J27: 164.08612 | K27: 164.73251 | L27: 165.39639 | M27: 166.08059 | N27: 166.78852 | O27: 167.52426 | P27: 168.29282 | Q27: 169.10046 | R27: 169.95508 | S27: 170.86696 | T27: 171.84977 | U27: 172.92225 | V27: 174.11118 | W27: 175.45665 | X27: 177.02278 | Y27: 178.92171 | Z27: 181.37766 | AA27: 184.95106 | AB27: 191.88347
A28: Interest | C28: 2246.454 | D28: 280.80675 | E28: 262.0863 | F28: 243.36585 | G28: 224.6454 | H28: 205.92495 | I28: 187.2045 | J28: 168.48405 | K28: 149.7636 | L28: 131.04315 | M28: 112.3227 | N28: 93.60225 | O28: 74.8818 | P28: 56.16135 | Q28: 37.4409 | R28: 18.72045 | S28: 0 | T28: 0 | U28: 0 | V28: 0 | W28: 0 | X28: 0 | Y28: 0 | Z28: 0 | AA28: 0 | AB28: 0
A29: Profit before tax | C29: 7682.3088 | D29: 183.09231 | E29: 197.91065 | F29: 212.56669 | G29: 227.05762 | H29: 241.38668 | I29: 255.54477 | J29: 269.5222 | K29: 283.31021 | L29: 296.8955 | M29: 310.27644 | N29: 323.42678 | O29: 336.33052 | P29: 348.98101 | Q29: 361.36528 | R29: 373.45211 | S29: 385.21729 | T29: 377.91947 | U29: 370.25584 | V29: 362.19388 | W29: 353.66624 | X29: 344.59416 | Y29: 334.85238 | Z29: 324.20519 | AA29: 312.0781 | AB29: 296.20749
A30: Tax depreciation | C30: 4687.7851 | D30: 1782.9 | E30: 1075.3272 | F30: 650.6159 | G30: 395.62654 | H30: 242.47521 | I30: 150.43143 | J30: 95.056779 | K30: 61.688049 | L30: 41.527191 | M30: 29.295245 | N30: 21.82471 | O30: 17.214962 | P30: 14.325509 | Q30: 12.471942 | R30: 11.243502 | S30: 10.393628 | T30: 9.7742779 | U30: 9.2965247 | V30: 8.9069141 | W30: 8.5732778 | X30: 8.2762221 | Y30: 8.004021 | Z30: 7.7495517 | AA30: 7.508456 | AB30: 7.2780368
A31: Tax | C31: 1824.196 | D31: 0 | E31: 0 | F31: 0 | G31: 0 | H31: 0 | I31: 0 | J31: 0 | K31: 0 | L31: 0 | M31: 0 | N31: 13.330691 | O31: 122.48724 | P31: 126.59209 | Q31: 130.37904 | R31: 133.9456 | S31: 137.35033 | T31: 135.91673 | U31: 134.37799 | V31: 132.74611 | W31: 131.02234 | X31: 129.20786 | Y31: 127.30233 | Z31: 125.30464 | AA31: 123.21236 | AB31: 121.02061
A32: Profit after tax | C32: 5858.1128 | D32: 183.09231 | E32: 197.91065 | F32: 212.56669 | G32: 227.05762 | H32: 241.38668 | I32: 255.54477 | J32: 269.5222 | K32: 283.31021 | L32: 296.8955 | M32: 310.27644 | N32: 310.09609 | O32: 213.84328 | P32: 222.38891 | Q32: 230.98624 | R32: 239.50651 | S32: 247.86696 | T32: 242.00274 | U32: 235.87785 | V32: 229.44776 | W32: 222.6439 | X32: 215.3863 | Y32: 207.55006 | Z32: 198.90055 | AA32: 188.86574 | AB32: 175.18687
A33: Cash flow
A34: Receivables | B34: ₹ cr | D34: 84.981583 | E34: 84.894035 | F34: 84.803441 | G34: 84.710406 | H34: 84.616346 | I34: 84.521218 | J34: 84.424976 | K34: 84.327776 | L34: 84.2293 | M34: 84.130775 | N34: 84.030516 | O34: 83.928242 | P34: 83.824999 | Q34: 83.721269 | R34: 83.615557 | S34: 83.507585 | T34: 83.397981 | U34: 83.287781 | V34: 83.177948 | W34: 83.06688 | X34: 82.954612 | Y34: 82.841466 | Z34: 82.728056 | AA34: 82.614786 | AB34: 82.501172
A35: Working capital change | C35: 82.501172 | D35: 84.981583 | E35: -0.087548549 | F35: -0.090594139 | G35: -0.093034976 | H35: -0.094059777 | I35: -0.095127876 | J35: -0.096241664 | K35: -0.097200639 | L35: -0.098476064 | M35: -0.098524556 | N35: -0.10025946 | O35: -0.10227372 | P35: -0.10324289 | Q35: -0.10372968 | R35: -0.10571276 | S35: -0.10797152 | T35: -0.1096036 | U35: -0.11020061 | V35: -0.10983241 | W35: -0.11106857 | X35: -0.11226775 | Y35: -0.11314577 | Z35: -0.11341017 | AA35: -0.11327055 | AB35: -0.11361335
A36: Battery augmentation | C36: 241.45214 | D36: 0 | E36: 13.968 | F36: 13.54896 | G36: 13.142491 | H36: 12.748216 | I36: 12.36577 | J36: 11.994797 | K36: 11.634953 | L36: 11.285904 | M36: 10.947327 | N36: 10.618907 | O36: 10.30034 | P36: 9.99133 | Q36: 9.6915901 | R36: 9.4008424 | S36: 9.1188171 | T36: 8.8452526 | U36: 8.579895 | V36: 8.3224982 | W36: 8.0728232 | X36: 7.8306385 | Y36: 7.5957194 | Z36: 7.3678478 | AA36: 7.1468124 | AB36: 6.932408
A37: CFADS | C37: 12033.591 | D37: 539.37848 | E37: 607.1595 | F37: 604.10626 | G37: 600.88303 | H37: 597.494 | I37: 593.93345 | J37: 590.19382 | K37: 586.26856 | L37: 582.14761 | M37: 577.83093 | N37: 559.96821 | O37: 446.05127 | P37: 436.955 | Q37: 427.93973 | R37: 418.88691 | S37: 409.72307 | T37: 405.11686 | U37: 400.3304 | V37: 395.34628 | W37: 390.1388 | X37: 384.69071 | Y37: 378.98919 | Z37: 373.02377 | AA37: 366.78326 | AB37: 360.25155
A38: Debt service | C38: 5366.529 | D38: 488.81175 | E38: 470.0913 | F38: 451.37085 | G38: 432.6504 | H38: 413.92995 | I38: 395.2095 | J38: 376.48905 | K38: 357.7686 | L38: 339.04815 | M38: 320.3277 | N38: 301.60725 | O38: 282.8868 | P38: 264.16635 | Q38: 245.4459 | R38: 226.72545 | S38: 0 | T38: 0 | U38: 0 | V38: 0 | W38: 0 | X38: 0 | Y38: 0 | Z38: 0 | AA38: 0 | AB38: 0
A39: Free cash to equity | C39: 7195.2878 | D39: 50.566731 | E39: 137.0682 | F39: 152.73541 | G39: 168.23263 | H39: 183.56405 | I39: 198.72395 | J39: 213.70477 | K39: 228.49996 | L39: 243.09946 | M39: 257.50323 | N39: 258.36096 | O39: 163.16447 | P39: 172.78865 | Q39: 182.49383 | R39: 192.16146 | S39: 409.72307 | T39: 405.11686 | U39: 400.3304 | V39: 395.34628 | W39: 390.1388 | X39: 384.69071 | Y39: 378.98919 | Z39: 373.02377 | AA39: 366.78326 | AB39: 888.47772
A40: Cumulative equity cash | B40: ₹ cr | D40: -1286.6083 | E40: -1149.5401 | F40: -996.80466 | G40: -828.57203 | H40: -645.00798 | I40: -446.28403 | J40: -232.57926 | K40: -4.079298 | L40: 239.02016 | M40: 496.52339 | N40: 754.88435 | O40: 918.04882 | P40: 1090.8375 | Q40: 1273.3313 | R40: 1465.4928 | S40: 1875.2158 | T40: 2280.3327 | U40: 2680.6631 | V40: 3076.0094 | W40: 3466.1482 | X40: 3850.8389 | Y40: 4229.8281 | Z40: 4602.8518 | AA40: 4969.6351 | AB40: 5858.1128
...
