Workbook

Sheet Cover
A4: SECI RTC-TM · bid financial model
A5: SECI/C&P/IPP/13/0020/25-26 · 200 MW round the clock · 25 years
A6: Prepared 2026-10-24 by Demo · Tender to Bid (TenderOS)
A7: The key results below are linked to the Live model tab: change an input there (blue cells) and they follow.
A9: Key results
A10: Bid tariff (₹/kWh) | B10: ='Live model'!$C$9 -> 8.0010717 | C10: Tariff that gives the 14.00% target equity IRR
A11: Equity IRR | B11: ='Live model'!$C$10 -> 0.14
A12: Project IRR | B12: ='Live model'!$C$12 -> 0.099563349
A13: Equity NPV at the target IRR (₹ cr) | B13: ='Live model'!$C$13 -> 2.5579538e-13
A14: Minimum DSCR | B14: ='Live model'!$C$15 -> 1.1572937
A15: Average DSCR | B15: ='Live model'!$C$16 -> 1.5536586
A16: Equity payback (year) | B16: ='Live model'!$C$19 -> 8
A17: Project cost (₹ cr) | B17: ='Live model'!$C$20 -> 7571.8719 | C17: ₹37.86 cr per contracted MW
A18: Debt (₹ cr) | B18: ='Live model'!$C$21 -> 5300.3103
A19: Equity (₹ cr) | B19: ='Live model'!$C$22 -> 2271.5616
A20: Levelised cost of supply (₹/kWh) | B20: ='Live model'!$C$17 -> 6.5775076 | C20: at a 10.0% discount rate
A21: Least-tariff sizing (HiGHS, ₹/kWh) | B21: 7.9948261 | C21: Screening tariff of the sizing; the bid tariff is from the full financial model
A22: Year-1 supply (MU) | B22: 1581.5235 | C22: 90.3% of contracted
A23: Year-1 market sale (MU) | B23: 0
A24: Revenue over 25 years (₹ cr) | B24: ='Live model'!$C$23 -> 29172.888
A25: Tender conditions | B25: 5 met, 0 not met
A27: Plant
A28: Contracted capacity (MW) | B28: 200 | C28: bid capacity
A29: Solar (MW) | B29: 910.82096 | C29: sized by the optimizer
A30: Battery power (MW) | B30: 743.33807
A31: Battery energy (MWh) | B31: 2973.3523
A33: Key inputs
A34: Bid capacity (MW) | B34: 200
A35: Solar | B35: CUF (AC) 25.0% · Capex 4 ₹ cr/MW · O&M 4 ₹ lakh/MW/yr
A36: Battery storage | B36: Discharge duration 4 hours · Round-trip efficiency 87.0% · Capex 1.2 ₹ cr/MWh · O&M 1.2 ₹ lakh/MWh/yr
A37: Financing | B37: equity IRR 14.0% · debt 70% at 9.00% for 15 years · tax 25.17%
A38: Market sale | B38: none
A40: Tender
A41: Procurer | B41: Solar Energy Corporation of India Limited (SECI)
A42: Tender | B42: SECI/C&P/IPP/13/0020/25-26 | C42: Supply of 1000 MW Round-the-Clock Thermal Mimic (RTC-TM) power from ISTS-connected RE projects
A43: Capacity | B43: 1000 MW
A44: Supply floors | B44: Peak Hours floor (every block) 90% · Off-peak floor (every block) 70%
A45: Least green share | B45: Not stated
A46: Mandatory solar | B46: Not stated
A47: PPA term | B47: 25 years
...

Sheet Live model
A1: SECI RTC-TM · bid financial model
A2: Every number below is a formula on the blue inputs and the optimiser's energy (green). Change a blue cell: the whole model, the returns and the Cover move with it.
A3: Colour key | B3: Input | C3: Optimiser | D3: Formula
A4: The optimiser's energy comes from the hourly HiGHS dispatch of every year; changing a plant size here moves its cost, not its energy (size the plant again in TenderOS for that).
A5: ₹ crore unless stated | B5: Unit | C5: Total / value | D5: Year 0 | E5: 1 | F5: =E5+1 -> 2 | G5: =F5+1 -> 3 | H5: =G5+1 -> 4 | I5: =H5+1 -> 5 | J5: =I5+1 -> 6 | K5: =J5+1 -> 7 | L5: =K5+1 -> 8 | M5: =L5+1 -> 9 | ... AC5: =AB5+1 -> 25
A7: Key results
C8: This workbook | D8: App | E8: Difference | F8: Same as app?
A9: Bid tariff | B9: ₹/kWh | C9: =$C$29 -> 8.0010717 | D9: 8.0010717 | E9: =IF(ISNUMBER(C9),C9-D9,"") -> 0 | F9: =IF(ISNUMBER(E9),IF(ABS(E9)<=0.000008001071731908118,"Yes","Changed"),"") -> Yes
A10: Equity IRR | B10: % | C10: =IFERROR(IRR(D165:AC165),"n/a") -> 0.14 | D10: 0.14 | E10: =IF(ISNUMBER(C10),C10-D10,"") -> 6.4259237e-11 | F10: =IF(ISNUMBER(E10),IF(ABS(E10)<=0.00001,"Yes","Changed"),"") -> Yes
A11: Equity IRR less the target | B11: % | C11: =IFERROR($C$10-$C$63,"n/a") -> 2.3078761e-13 | D11: -6.4028449e-11 | E11: =IF(ISNUMBER(C11),C11-D11,"") -> 6.4259237e-11 | F11: =IF(ISNUMBER(E11),IF(ABS(E11)<=0.00001,"Yes","Changed"),"") -> Yes
A12: Project IRR | B12: % | C12: =IFERROR(IRR(D169:AC169),"n/a") -> 0.09956335 | D12: 0.099563349 | E12: =IF(ISNUMBER(C12),C12-D12,"") -> 2.007039e-10 | F12: =IF(ISNUMBER(E12),IF(ABS(E12)<=0.00001,"Yes","Changed"),"") -> Yes
A13: Equity NPV at the target IRR | B13: ₹ cr | C13: =D165+NPV($C$63,E165:AC165) -> -6.3948846e-14 | D13: 2.5579538e-13 | E13: =IF(ISNUMBER(C13),C13-D13,"") -> -3.1974423e-13 | F13: =IF(ISNUMBER(E13),IF(ABS(E13)<=0.000001,"Yes","Changed"),"") -> Yes
A14: Project NPV at the discount rate | B14: ₹ cr | C14: =D169+NPV($C$64,E169:AC169) -> -23.208403 | D14: -23.208403 | E14: =IF(ISNUMBER(C14),C14-D14,"") -> -2.8421709e-13 | F14: =IF(ISNUMBER(E14),IF(ABS(E14)<=0.00002320840277829518,"Yes","Changed"),"") -> Yes
A15: Minimum DSCR | B15: × | C15: =IF(COUNT(E162:AC162)=0,"",MIN(E162:AC162)) -> 1.1572937 | D15: 1.1572937 | E15: =IF(ISNUMBER(C15),C15-D15,"") -> 0 | F15: =IF(ISNUMBER(E15),IF(ABS(E15)<=0.00000115729366418498,"Yes","Changed"),"") -> Yes
A16: Average DSCR | B16: × | C16: =IF(COUNT(E162:AC162)=0,"",AVERAGE(E162:AC162)) -> 1.5536586 | D16: 1.5536586 | E16: =IF(ISNUMBER(C16),C16-D16,"") -> 2.220446e-16 | F16: =IF(ISNUMBER(E16),IF(ABS(E16)<=0.0000015536586071699471,"Yes","Changed"),"") -> Yes
A17: Levelised cost of supply | B17: ₹/kWh | C17: =IF(C174>0,($C$80+C173)*10/C174,"") -> 6.5775076 | D17: 6.5775076 | E17: =IF(ISNUMBER(C17),C17-D17,"") -> 8.8817842e-16 | F17: =IF(ISNUMBER(E17),IF(ABS(E17)<=0.00000657750757800655,"Yes","Changed"),"") -> Yes
A18: Levelised tariff | B18: ₹/kWh | C18: =IF(C174>0,C175*10/C174,"") -> 8.0010717 | D18: 8.0010717 | E18: =IF(ISNUMBER(C18),C18-D18,"") -> -1.7763568e-15 | F18: =IF(ISNUMBER(E18),IF(ABS(E18)<=0.00000800107173190812,"Yes","Changed"),"") -> Yes
A19: Equity payback | B19: year | C19: =IF(COUNT(E167:AC167)=0,"beyond the term",MIN(E167:AC167)) -> 8 | D19: 8 | E19: =IF(ISNUMBER(C19),C19-D19,"") -> 0 | F19: =IF(ISNUMBER(E19),IF(ABS(E19)<=0.000008,"Yes","Changed"),"") -> Yes
A20: Project cost | B20: ₹ cr | C20: =$C$80 -> 7571.8719 | D20: 7571.8719 | E20: =IF(ISNUMBER(C20),C20-D20,"") -> 0 | F20: =IF(ISNUMBER(E20),IF(ABS(E20)<=0.007571871924760596,"Yes","Changed"),"") -> Yes
A21: Debt | B21: ₹ cr | C21: =$C$81 -> 5300.3103 | D21: 5300.3103 | E21: =IF(ISNUMBER(C21),C21-D21,"") -> 0 | F21: =IF(ISNUMBER(E21),IF(ABS(E21)<=0.005300310347332417,"Yes","Changed"),"") -> Yes
A22: Equity | B22: ₹ cr | C22: =$C$82 -> 2271.5616 | D22: 2271.5616 | E22: =IF(ISNUMBER(C22),C22-D22,"") -> 0 | F22: =IF(ISNUMBER(E22),IF(ABS(E22)<=0.0022715615774281796,"Yes","Changed"),"") -> Yes
A23: Revenue over 25 years | B23: ₹ cr | C23: =C111 -> 29172.888 | D23: 29172.888 | E23: =IF(ISNUMBER(C23),C23-D23,"") -> 0 | F23: =IF(ISNUMBER(E23),IF(ABS(E23)<=0.029172888207863342,"Yes","Changed"),"") -> Yes
A24: Model checks | C24: =IF(AND($C$189="OK",$C$190="OK",$C$191="OK",$C$192="OK"),"OK","CHECK") -> OK | F24: =IF(C24="OK","OK","CHECK") -> OK
A25: To price the bid again after changing an input: Data › What-If Analysis › Goal Seek, set the cell "Equity IRR less the target" to 0 by changing the bid tariff.
A27: Inputs
A28: Tariff
A29: Bid tariff | B29: ₹/kWh | C29: 8.0010717 | D29: Solved in TenderOS for the target equity IRR
A30: Tariff escalation | B30: %/yr | C30: 0 | D30: Industry benchmark
A31: Plant (sized by the optimiser)
A32: Solar | B32: MW | C32: 910.82096 | D32: HiGHS sizing
A33: Battery power | B33: MW | C33: 743.33807 | D33: HiGHS sizing
A34: Battery energy | B34: MWh | C34: 2973.3523 | D34: HiGHS sizing
A35: Capital cost
A36: Solar | B36: ₹ cr/MW | C36: 4 | D36: Industry benchmark
A37: Battery energy | B37: ₹ cr/MWh | C37: 1.2 | D37: Industry benchmark
A38: Battery power conversion | B38: ₹ cr/MW | C38: 0 | D38: Included in the energy price
A39: Transmission / evacuation | B39: ₹ cr | C39: 0 | D39: Industry benchmark
A40: Pre-operative and IDC | B40: % of hard cost | C40: 0.05 | D40: Industry benchmark
A41: Operating cost
A42: Solar O&M | B42: ₹ lakh/MW/yr | C42: 4 | D42: Industry benchmark
...

Sheet Tender conditions
A1: Condition | B1: Tender says | C1: Page | D1: Quote | E1: Plant and bid | F1: Status
A2: Bid capacity | B2: 1,000 MW; one bidder 50–500 MW | C2: 1 | D2: a minimum quantum of cumulative Contracted Capacity of 50 MW and a maximum quantum of 500 MW | E2: 200 MW bid | F2: Met
A3: Peak Hours floor (every block) | B3: At least 90% of contracted capacity in every peak time-block; shortfall costs 1.5 × tariff | C3: 2 | D3: (i) a minimum DFR of 90% in each time-block during the Peak Hours | E3: 91.4% of the hours at the floor; 73.82 MU short in the worst modelled year | F3: Noted
A4: Off-peak floor (every block) | B4: At least 70% of contracted capacity in every off-peak time-block; shortfall costs 1.5 × tariff | C4: 2 | D4: (ii) a minimum DFR of 70% in each time-block during the off-Peak Hours. | E4: 98.0% of the hours at the floor; 2.50 MU short in the worst modelled year | F4: Noted
A5: Peak hours | B5: Any 6 of the 16 hours (the Buying Entity picks 6 hours between 18:00 and 10:00, day-ahead) a day | C5: 2 | D5: The Buying Entity shall choose any 6 hours, on a daily basis, between 18:00 Hrs. in the evening of a day and 10:00 Hrs. in the morning of the subsequent day | E5: Checked in the chosen window | F5: Met
A6: Energy storage | B6: Mandatory | C6: 2 | D6: Energy Storage Systems (ESS) shall mandatorily constitute part of the Project. It is clarified that ESS charged using a source other than RE power would not qualify as RE power. | E6: 743 MW / 2,973 MWh | F6: Met
A7: What may be sold in the market | B7: Free to sell to any third party or power exchange, no NOC needed | C7: 19 | D7: the SECI/RPD is free to sell power in excess of the Contracted Capacity in any time-block, to any third party or power exchange, without requiring any NOC from Buying Entity. | E7: Nothing sold | F7: Met
A8: PPA term | B8: 25 years | C8: 34 | D8: The PPAs shall be valid for a period of 25 years from the SCSD. | E8: Modelled and financed over 25 years | F8: Met
A9: Ceiling tariff | B9: Not stated | C9: 60 | D9: SECI reserves the right to cancel any or all of the bids in view of higher tariff discovered after e-RA. | E9: Bid tariff ₹8.001/kWh | F9: Not required
A10: Supply start | B10: 07.08.2028 | C10: 2 | D10: The Scheduled Commencement of Supply Date (SCSD) for supplying power from the full Project capacity shall be the date as on 24 months from the Effective Date of the PPA | E10: Build schedule is not modelled | F10: Noted

Sheet Inputs
A1: Group | B1: Input | C1: Value | D1: Unit | E1: Source
A2: Bid | B2: Bid capacity | C2: 200 | D2: MW | E2: Your input
A3: Bid | B3: Sized for the greenshoe | C3: No | E3: Your input
A4: Solar | B4: Capacity | C4: automatic limit | D4: MW | E4: Upper limit for the optimizer
A5: Solar | B5: CUF (AC) | C5: 0.25 | D5: % | E5: Industry benchmark
A6: Solar | B6: DC:AC ratio | C6: 1.4 | D6: × | E6: Industry benchmark
A7: Solar | B7: Annual degradation | C7: 0.005 | D7: % | E7: Industry benchmark
A8: Solar | B8: Capex | C8: 4 | D8: ₹ cr/MW | E8: Industry benchmark
A9: Solar | B9: O&M | C9: 4 | D9: ₹ lakh/MW/yr | E9: Industry benchmark
A10: Battery storage | B10: Capacity | C10: automatic limit | D10: MW | E10: Upper limit for the optimizer
A11: Battery storage | B11: Discharge duration | C11: 4 hours | E11: Industry benchmark
A12: Battery storage | B12: Round-trip efficiency | C12: 0.87 | D12: % | E12: Industry benchmark
A13: Battery storage | B13: Minimum state of charge | C13: 0.05 | D13: % | E13: Industry benchmark
A14: Battery storage | B14: Maximum state of charge | C14: 0.95 | D14: % | E14: Industry benchmark
A15: Battery storage | B15: Capacity fade | C15: 0.02 | D15: % | E15: Industry benchmark
A16: Battery storage | B16: Augmentation | C16: Every year | E16: Industry benchmark
A17: Battery storage | B17: Capex | C17: 1.2 | D17: ₹ cr/MWh | E17: Industry benchmark
A18: Battery storage | B18: O&M | C18: 1.2 | D18: ₹ lakh/MWh/yr | E18: Industry benchmark
A19: Financing | B19: Target equity IRR | C19: 0.14 | D19: % | E19: Industry benchmark
A20: Financing | B20: Debt share | C20: 0.7 | D20: % | E20: Industry benchmark
A21: Financing | B21: Interest rate | C21: 0.09 | D21: % | E21: Industry benchmark
A22: Financing | B22: Loan tenor | C22: 15 | D22: years | E22: Industry benchmark
A23: Financing | B23: Corporate tax | C23: 0.2517 | D23: % | E23: Industry benchmark
A24: Financing | B24: O&M escalation | C24: 0.05 | D24: % | E24: Industry benchmark
A25: Financing | B25: Insurance | C25: 0.003 | D25: % | E25: Industry benchmark
A26: Financing | B26: Tariff escalation | C26: 0 | D26: % | E26: Industry benchmark
A27: Financing | B27: Pre-operative & IDC | C27: 0.05 | D27: % | E27: Industry benchmark
A28: Financing | B28: Transmission / evacuation | C28: 0 | D28: ₹ cr | E28: Industry benchmark
A29: Financing | B29: Repayment | C29: equal | E29: Model default (editable on Financials)
A30: Financing | B30: Tax depreciation | C30: wdv | E30: Model default (editable on Financials)
A31: Financing | B31: WDV rate | C31: 0.4 | D31: % | E31: Model default (editable on Financials)
A32: Financing | B32: Book life | C32: 25 | D32: years | E32: Model default (editable on Financials)
A33: Financing | B33: Salvage value | C33: 0.1 | D33: % | E33: Model default (editable on Financials)
A34: Financing | B34: Receivable days | C34: 45 | D34: days | E34: Model default (editable on Financials)
A35: Financing | B35: Discount rate (LCOE, NPV) | C35: 0.1 | D35: % | E35: Model default (editable on Financials)
A36: Market | B36: Sell in the market | C36: No | E36: Industry benchmark

Sheet Plant and capex
A1: Item | B1: Value | C1: Note
A2: Contracted capacity (MW) | B2: 200 | C2: bid capacity
A3: Solar (MW) | B3: 910.82096 | C3: sized by the optimizer
A4: Battery power (MW) | B4: 743.33807
A5: Battery energy (MWh) | B5: 2973.3523
A7: Capex | B7: ₹ crore | C7: Note
A8: Solar | B8: 3825.4481
A9: Battery storage | B9: 3746.4239
A10: Transmission / evacuation | B10: 0
A11: Total project cost (incl. pre-operative & IDC) | B11: 7571.8719 | C11: pre-operative 5.0% of hard cost
A12: Debt | B12: 5300.3103 | C12: 70%
A13: Equity | B13: 2271.5616

Sheet Revenue and costs (values)
A1: ₹ crore unless stated | B1: Unit | C1: Total | D1: Year 1 | E1: Year 2 | F1: Year 3 | G1: Year 4 | H1: Year 5 | I1: Year 6 | J1: Year 7 | K1: Year 8 | L1: Year 9 | M1: Year 10 | N1: Year 11 | O1: Year 12 | P1: Year 13 | Q1: Year 14 | R1: Year 15 | S1: Year 16 | T1: Year 17 | U1: Year 18 | V1: Year 19 | W1: Year 20 | X1: Year 21 | Y1: Year 22 | Z1: Year 23 | AA1: Year 24 | AB1: Year 25
A2: Energy and tariff
A3: Contracted energy | B3: MU | C3: 43800 | D3: 1752 | E3: 1752 | F3: 1752 | G3: 1752 | H3: 1752 | I3: 1752 | J3: 1752 | K3: 1752 | L3: 1752 | M3: 1752 | N3: 1752 | O3: 1752 | P3: 1752 | Q3: 1752 | R3: 1752 | S3: 1752 | T3: 1752 | U3: 1752 | V3: 1752 | W3: 1752 | X3: 1752 | Y3: 1752 | Z3: 1752 | AA3: 1752 | AB3: 1752
A4: Delivered to the procurer | B4: MU | C4: 38865.853 | D4: 1581.5235 | E4: 1579.2827 | F4: 1577.042 | G4: 1574.8012 | H4: 1572.5604 | I4: 1570.3196 | J4: 1568.0788 | K4: 1565.838 | L4: 1563.5973 | M4: 1561.3565 | N4: 1559.1157 | O4: 1556.8749 | P4: 1554.6341 | Q4: 1552.3934 | R4: 1550.1526 | S4: 1547.9118 | T4: 1545.671 | U4: 1543.4302 | V4: 1541.1895 | W4: 1538.9487 | X4: 1536.7079 | Y4: 1534.4671 | Z4: 1532.2263 | AA4: 1529.9855 | AB4: 1527.7448
A5: Delivered ÷ contracted | D5: 0.90269607 | E5: 0.90141709 | F5: 0.9001381 | G5: 0.89885912 | H5: 0.89758013 | I5: 0.89630115 | J5: 0.89502216 | K5: 0.89374318 | L5: 0.89246419 | M5: 0.89118521 | N5: 0.88990622 | O5: 0.88862724 | P5: 0.88734825 | Q5: 0.88606927 | R5: 0.88479028 | S5: 0.8835113 | T5: 0.88223231 | U5: 0.88095333 | V5: 0.87967434 | W5: 0.87839536 | X5: 0.87711637 | Y5: 0.87583739 | Z5: 0.8745584 | AA5: 0.87327942 | AB5: 0.87200043
A6: Sold in the market | B6: MU | C6: 0 | D6: 0 | E6: 0 | F6: 0 | G6: 0 | H6: 0 | I6: 0 | J6: 0 | K6: 0 | L6: 0 | M6: 0 | N6: 0 | O6: 0 | P6: 0 | Q6: 0 | R6: 0 | S6: 0 | T6: 0 | U6: 0 | V6: 0 | W6: 0 | X6: 0 | Y6: 0 | Z6: 0 | AA6: 0 | AB6: 0
A7: Tariff | B7: ₹/kWh | D7: 8.0010717 | E7: 8.0010717 | F7: 8.0010717 | G7: 8.0010717 | H7: 8.0010717 | I7: 8.0010717 | J7: 8.0010717 | K7: 8.0010717 | L7: 8.0010717 | M7: 8.0010717 | N7: 8.0010717 | O7: 8.0010717 | P7: 8.0010717 | Q7: 8.0010717 | R7: 8.0010717 | S7: 8.0010717 | T7: 8.0010717 | U7: 8.0010717 | V7: 8.0010717 | W7: 8.0010717 | X7: 8.0010717 | Y7: 8.0010717 | Z7: 8.0010717 | AA7: 8.0010717 | AB7: 8.0010717
A8: Revenue
A9: PPA supply revenue | C9: 31096.848 | D9: 1265.3883 | E9: 1263.5954 | F9: 1261.8026 | G9: 1260.0097 | H9: 1258.2169 | I9: 1256.424 | J9: 1254.6311 | K9: 1252.8383 | L9: 1251.0454 | M9: 1249.2525 | N9: 1247.4597 | O9: 1245.6668 | P9: 1243.8739 | Q9: 1242.0811 | R9: 1240.2882 | S9: 1238.4953 | T9: 1236.7025 | U9: 1234.9096 | V9: 1233.1167 | W9: 1231.3239 | X9: 1229.531 | Y9: 1227.7381 | Z9: 1225.9453 | AA9: 1224.1524 | AB9: 1222.3595
A10: Market sale revenue | C10: 0 | D10: 0 | E10: 0 | F10: 0 | G10: 0 | H10: 0 | I10: 0 | J10: 0 | K10: 0 | L10: 0 | M10: 0 | N10: 0 | O10: 0 | P10: 0 | Q10: 0 | R10: 0 | S10: 0 | T10: 0 | U10: 0 | V10: 0 | W10: 0 | X10: 0 | Y10: 0 | Z10: 0 | AA10: 0 | AB10: 0
A11: Shortfall penalty | C11: 1923.96 | D11: 62.322351 | E11: 63.542022 | F11: 64.761692 | G11: 65.981363 | H11: 67.201034 | I11: 68.420704 | J11: 69.640375 | K11: 70.860046 | L11: 72.079716 | M11: 73.299387 | N11: 74.519057 | O11: 75.738728 | P11: 76.958399 | Q11: 78.178069 | R11: 79.39774 | S11: 80.617411 | T11: 81.837081 | U11: 83.056752 | V11: 84.276423 | W11: 85.496093 | X11: 86.715764 | Y11: 87.935434 | Z11: 89.155105 | AA11: 90.374776 | AB11: 91.594446
A12: Total revenue | C12: 29172.888 | D12: 1203.066 | E12: 1200.0534 | F12: 1197.0409 | G12: 1194.0284 | H12: 1191.0158 | I12: 1188.0033 | J12: 1184.9907 | K12: 1181.9782 | L12: 1178.9657 | M12: 1175.9531 | N12: 1172.9406 | O12: 1169.9281 | P12: 1166.9155 | Q12: 1163.903 | R12: 1160.8905 | S12: 1157.8779 | T12: 1154.8654 | U12: 1151.8528 | V12: 1148.8403 | W12: 1145.8278 | X12: 1142.8152 | Y12: 1139.8027 | Z12: 1136.7902 | AA12: 1133.7776 | AB12: 1130.7651
A13: Operating costs
A14: O&M | C14: 3441.7474 | D14: 72.113066 | E14: 75.718719 | F14: 79.504655 | G14: 83.479888 | H14: 87.653882 | I14: 92.036576 | J14: 96.638405 | K14: 101.47033 | L14: 106.54384 | M14: 111.87103 | N14: 117.46459 | O14: 123.33781 | P14: 129.50471 | Q14: 135.97994 | R14: 142.77894 | S14: 149.91788 | T14: 157.41378 | U14: 165.28447 | V14: 173.54869 | W14: 182.22613 | X14: 191.33743 | Y14: 200.9043 | Z14: 210.94952 | AA14: 221.497 | AB14: 232.57184
A15: Insurance | C15: 540.84799 | D15: 21.63392 | E15: 21.63392 | F15: 21.63392 | G15: 21.63392 | H15: 21.63392 | I15: 21.63392 | J15: 21.63392 | K15: 21.63392 | L15: 21.63392 | M15: 21.63392 | N15: 21.63392 | O15: 21.63392 | P15: 21.63392 | Q15: 21.63392 | R15: 21.63392 | S15: 21.63392 | T15: 21.63392 | U15: 21.63392 | V15: 21.63392 | W15: 21.63392 | X15: 21.63392 | Y15: 21.63392 | Z15: 21.63392 | AA15: 21.63392 | AB15: 21.63392
A16: Other fixed cost | C16: 0 | D16: 0 | E16: 0 | F16: 0 | G16: 0 | H16: 0 | I16: 0 | J16: 0 | K16: 0 | L16: 0 | M16: 0 | N16: 0 | O16: 0 | P16: 0 | Q16: 0 | R16: 0 | S16: 0 | T16: 0 | U16: 0 | V16: 0 | W16: 0 | X16: 0 | Y16: 0 | Z16: 0 | AA16: 0 | AB16: 0
A17: Total operating cost | C17: 3982.5954 | D17: 93.746986 | E17: 97.352639 | F17: 101.13857 | G17: 105.11381 | H17: 109.2878 | I17: 113.6705 | J17: 118.27233 | K17: 123.10425 | L17: 128.17776 | M17: 133.50495 | N17: 139.09851 | O17: 144.97173 | P17: 151.13863 | Q17: 157.61386 | R17: 164.41286 | S17: 171.5518 | T17: 179.0477 | U17: 186.91839 | V17: 195.18261 | W17: 203.86005 | X17: 212.97135 | Y17: 222.53822 | Z17: 232.58344 | AA17: 243.13091 | AB17: 254.20576
A18: Capital spend in operation
A19: Battery augmentation | C19: 1712.6509 | D19: 0 | E19: 71.360455 | F19: 71.360455 | G19: 71.360455 | H19: 71.360455 | I19: 71.360455 | J19: 71.360455 | K19: 71.360455 | L19: 71.360455 | M19: 71.360455 | N19: 71.360455 | O19: 71.360455 | P19: 71.360455 | Q19: 71.360455 | R19: 71.360455 | S19: 71.360455 | T19: 71.360455 | U19: 71.360455 | V19: 71.360455 | W19: 71.360455 | X19: 71.360455 | Y19: 71.360455 | Z19: 71.360455 | AA19: 71.360455 | AB19: 71.360455

Sheet Financial model (values)
A1: ₹ crore unless stated | B1: Unit | C1: Total | D1: Year 1 | E1: Year 2 | F1: Year 3 | G1: Year 4 | H1: Year 5 | I1: Year 6 | J1: Year 7 | K1: Year 8 | L1: Year 9 | M1: Year 10 | N1: Year 11 | O1: Year 12 | P1: Year 13 | Q1: Year 14 | R1: Year 15 | S1: Year 16 | T1: Year 17 | U1: Year 18 | V1: Year 19 | W1: Year 20 | X1: Year 21 | Y1: Year 22 | Z1: Year 23 | AA1: Year 24 | AB1: Year 25
A2: Energy and tariff
A3: Contracted energy | B3: MU | C3: 43800 | D3: 1752 | E3: 1752 | F3: 1752 | G3: 1752 | H3: 1752 | I3: 1752 | J3: 1752 | K3: 1752 | L3: 1752 | M3: 1752 | N3: 1752 | O3: 1752 | P3: 1752 | Q3: 1752 | R3: 1752 | S3: 1752 | T3: 1752 | U3: 1752 | V3: 1752 | W3: 1752 | X3: 1752 | Y3: 1752 | Z3: 1752 | AA3: 1752 | AB3: 1752
A4: Delivered to the procurer | B4: MU | C4: 38865.853 | D4: 1581.5235 | E4: 1579.2827 | F4: 1577.042 | G4: 1574.8012 | H4: 1572.5604 | I4: 1570.3196 | J4: 1568.0788 | K4: 1565.838 | L4: 1563.5973 | M4: 1561.3565 | N4: 1559.1157 | O4: 1556.8749 | P4: 1554.6341 | Q4: 1552.3934 | R4: 1550.1526 | S4: 1547.9118 | T4: 1545.671 | U4: 1543.4302 | V4: 1541.1895 | W4: 1538.9487 | X4: 1536.7079 | Y4: 1534.4671 | Z4: 1532.2263 | AA4: 1529.9855 | AB4: 1527.7448
A5: Delivered ÷ contracted | D5: 0.90269607 | E5: 0.90141709 | F5: 0.9001381 | G5: 0.89885912 | H5: 0.89758013 | I5: 0.89630115 | J5: 0.89502216 | K5: 0.89374318 | L5: 0.89246419 | M5: 0.89118521 | N5: 0.88990622 | O5: 0.88862724 | P5: 0.88734825 | Q5: 0.88606927 | R5: 0.88479028 | S5: 0.8835113 | T5: 0.88223231 | U5: 0.88095333 | V5: 0.87967434 | W5: 0.87839536 | X5: 0.87711637 | Y5: 0.87583739 | Z5: 0.8745584 | AA5: 0.87327942 | AB5: 0.87200043
A6: Sold in the market | B6: MU | C6: 0 | D6: 0 | E6: 0 | F6: 0 | G6: 0 | H6: 0 | I6: 0 | J6: 0 | K6: 0 | L6: 0 | M6: 0 | N6: 0 | O6: 0 | P6: 0 | Q6: 0 | R6: 0 | S6: 0 | T6: 0 | U6: 0 | V6: 0 | W6: 0 | X6: 0 | Y6: 0 | Z6: 0 | AA6: 0 | AB6: 0
A7: Tariff | B7: ₹/kWh | D7: 8.0010717 | E7: 8.0010717 | F7: 8.0010717 | G7: 8.0010717 | H7: 8.0010717 | I7: 8.0010717 | J7: 8.0010717 | K7: 8.0010717 | L7: 8.0010717 | M7: 8.0010717 | N7: 8.0010717 | O7: 8.0010717 | P7: 8.0010717 | Q7: 8.0010717 | R7: 8.0010717 | S7: 8.0010717 | T7: 8.0010717 | U7: 8.0010717 | V7: 8.0010717 | W7: 8.0010717 | X7: 8.0010717 | Y7: 8.0010717 | Z7: 8.0010717 | AA7: 8.0010717 | AB7: 8.0010717
A8: Revenue
A9: PPA supply revenue | C9: 31096.848 | D9: 1265.3883 | E9: 1263.5954 | F9: 1261.8026 | G9: 1260.0097 | H9: 1258.2169 | I9: 1256.424 | J9: 1254.6311 | K9: 1252.8383 | L9: 1251.0454 | M9: 1249.2525 | N9: 1247.4597 | O9: 1245.6668 | P9: 1243.8739 | Q9: 1242.0811 | R9: 1240.2882 | S9: 1238.4953 | T9: 1236.7025 | U9: 1234.9096 | V9: 1233.1167 | W9: 1231.3239 | X9: 1229.531 | Y9: 1227.7381 | Z9: 1225.9453 | AA9: 1224.1524 | AB9: 1222.3595
A10: Market sale revenue | C10: 0 | D10: 0 | E10: 0 | F10: 0 | G10: 0 | H10: 0 | I10: 0 | J10: 0 | K10: 0 | L10: 0 | M10: 0 | N10: 0 | O10: 0 | P10: 0 | Q10: 0 | R10: 0 | S10: 0 | T10: 0 | U10: 0 | V10: 0 | W10: 0 | X10: 0 | Y10: 0 | Z10: 0 | AA10: 0 | AB10: 0
A11: Shortfall penalty | C11: 1923.96 | D11: 62.322351 | E11: 63.542022 | F11: 64.761692 | G11: 65.981363 | H11: 67.201034 | I11: 68.420704 | J11: 69.640375 | K11: 70.860046 | L11: 72.079716 | M11: 73.299387 | N11: 74.519057 | O11: 75.738728 | P11: 76.958399 | Q11: 78.178069 | R11: 79.39774 | S11: 80.617411 | T11: 81.837081 | U11: 83.056752 | V11: 84.276423 | W11: 85.496093 | X11: 86.715764 | Y11: 87.935434 | Z11: 89.155105 | AA11: 90.374776 | AB11: 91.594446
A12: Total revenue | C12: 29172.888 | D12: 1203.066 | E12: 1200.0534 | F12: 1197.0409 | G12: 1194.0284 | H12: 1191.0158 | I12: 1188.0033 | J12: 1184.9907 | K12: 1181.9782 | L12: 1178.9657 | M12: 1175.9531 | N12: 1172.9406 | O12: 1169.9281 | P12: 1166.9155 | Q12: 1163.903 | R12: 1160.8905 | S12: 1157.8779 | T12: 1154.8654 | U12: 1151.8528 | V12: 1148.8403 | W12: 1145.8278 | X12: 1142.8152 | Y12: 1139.8027 | Z12: 1136.7902 | AA12: 1133.7776 | AB12: 1130.7651
A13: Operating costs
A14: O&M | C14: 3441.7474 | D14: 72.113066 | E14: 75.718719 | F14: 79.504655 | G14: 83.479888 | H14: 87.653882 | I14: 92.036576 | J14: 96.638405 | K14: 101.47033 | L14: 106.54384 | M14: 111.87103 | N14: 117.46459 | O14: 123.33781 | P14: 129.50471 | Q14: 135.97994 | R14: 142.77894 | S14: 149.91788 | T14: 157.41378 | U14: 165.28447 | V14: 173.54869 | W14: 182.22613 | X14: 191.33743 | Y14: 200.9043 | Z14: 210.94952 | AA14: 221.497 | AB14: 232.57184
A15: Insurance | C15: 540.84799 | D15: 21.63392 | E15: 21.63392 | F15: 21.63392 | G15: 21.63392 | H15: 21.63392 | I15: 21.63392 | J15: 21.63392 | K15: 21.63392 | L15: 21.63392 | M15: 21.63392 | N15: 21.63392 | O15: 21.63392 | P15: 21.63392 | Q15: 21.63392 | R15: 21.63392 | S15: 21.63392 | T15: 21.63392 | U15: 21.63392 | V15: 21.63392 | W15: 21.63392 | X15: 21.63392 | Y15: 21.63392 | Z15: 21.63392 | AA15: 21.63392 | AB15: 21.63392
A16: Other fixed cost | C16: 0 | D16: 0 | E16: 0 | F16: 0 | G16: 0 | H16: 0 | I16: 0 | J16: 0 | K16: 0 | L16: 0 | M16: 0 | N16: 0 | O16: 0 | P16: 0 | Q16: 0 | R16: 0 | S16: 0 | T16: 0 | U16: 0 | V16: 0 | W16: 0 | X16: 0 | Y16: 0 | Z16: 0 | AA16: 0 | AB16: 0
A17: Total operating cost | C17: 3982.5954 | D17: 93.746986 | E17: 97.352639 | F17: 101.13857 | G17: 105.11381 | H17: 109.2878 | I17: 113.6705 | J17: 118.27233 | K17: 123.10425 | L17: 128.17776 | M17: 133.50495 | N17: 139.09851 | O17: 144.97173 | P17: 151.13863 | Q17: 157.61386 | R17: 164.41286 | S17: 171.5518 | T17: 179.0477 | U17: 186.91839 | V17: 195.18261 | W17: 203.86005 | X17: 212.97135 | Y17: 222.53822 | Z17: 232.58344 | AA17: 243.13091 | AB17: 254.20576
A18: Profit and loss
A19: EBITDA | C19: 25190.293 | D19: 1109.319 | E19: 1102.7008 | F19: 1095.9023 | G19: 1088.9145 | H19: 1081.728 | I19: 1074.3328 | J19: 1066.7184 | K19: 1058.874 | L19: 1050.7879 | M19: 1042.4482 | N19: 1033.8421 | O19: 1024.9563 | P19: 1015.7769 | Q19: 1006.2891 | R19: 996.4776 | S19: 986.32612 | T19: 975.81769 | U19: 964.93446 | V19: 953.6577 | W19: 941.96773 | X19: 929.84389 | Y19: 917.26448 | Z19: 904.20673 | AA19: 890.64672 | AB19: 876.55933
A20: Book depreciation | C20: 8527.3356 | D20: 272.58739 | E20: 275.56074 | F20: 278.66337 | G20: 281.90703 | H20: 285.30514 | I20: 288.87317 | J20: 292.62898 | K20: 296.59345 | L20: 300.79112 | M20: 305.25115 | N20: 310.00852 | O20: 315.10569 | P20: 320.59496 | Q20: 326.54166 | R20: 333.02898 | S20: 340.16502 | T20: 348.09396 | U20: 357.01402 | V20: 367.20837 | W20: 379.10178 | X20: 393.37387 | Y20: 411.21398 | Z20: 435.0008 | AA20: 470.68103 | AB20: 542.04148
A21: Interest | C21: 3816.2235 | D21: 477.02793 | E21: 445.22607 | F21: 413.42421 | G21: 381.62235 | H21: 349.82048 | I21: 318.01862 | J21: 286.21676 | K21: 254.4149 | L21: 222.61303 | M21: 190.81117 | N21: 159.00931 | O21: 127.20745 | P21: 95.405586 | Q21: 63.603724 | R21: 31.801862 | S21: 1.330136e-13 | T21: 1.330136e-13 | U21: 1.330136e-13 | V21: 1.330136e-13 | W21: 1.330136e-13 | X21: 1.330136e-13 | Y21: 1.330136e-13 | Z21: 1.330136e-13 | AA21: 1.330136e-13 | AB21: 1.330136e-13
A22: Profit before tax | C22: 12846.734 | D22: 359.70365 | E22: 381.91398 | F22: 403.81474 | G22: 425.38517 | H22: 446.60239 | I22: 467.441 | J22: 487.87268 | K22: 507.86562 | L22: 527.38375 | M22: 546.38586 | N22: 564.82427 | O22: 582.64319 | P22: 599.77636 | Q22: 616.14375 | R22: 631.64676 | S22: 646.16109 | T22: 627.72372 | U22: 607.92044 | V22: 586.44933 | W22: 562.86595 | X22: 536.47002 | Y22: 506.0505 | Z22: 469.20593 | AA22: 419.96569 | AB22: 334.51785
A23: Tax depreciation | C23: 9177.4611 | D23: 3028.7488 | E23: 1845.7934 | F23: 1136.0202 | G23: 710.15633 | H23: 454.63798 | I23: 301.32697 | J23: 209.34036 | K23: 154.1484 | L23: 121.03322 | M23: 101.16412 | N23: 89.242651 | O23: 82.089772 | P23: 77.798045 | Q23: 75.223009 | R23: 73.677987 | S23: 72.750974 | T23: 72.194766 | U23: 71.861042 | V23: 71.660807 | W23: 71.540666 | X23: 71.468582 | Y23: 71.425331 | Z23: 71.39938 | AA23: 71.38381 | AB23: 71.374468
A24: Tax | C24: 3069.8863 | D24: 0 | E24: 0 | F24: 0 | G24: 0 | H24: 0 | I24: 0 | J24: 0 | K24: 0 | L24: 0 | M24: 0 | N24: 39.202443 | O24: 205.3014 | P24: 212.07569 | Q24: 218.34029 | R24: 224.26413 | S24: 229.94686 | T24: 227.44189 | U24: 224.78658 | V24: 221.99862 | W24: 219.08649 | X24: 216.05306 | Y24: 212.89771 | Z24: 209.61761 | AA24: 206.20847 | AB24: 202.66503
A25: Profit after tax | C25: 9776.8474 | D25: 359.70365 | E25: 381.91398 | F25: 403.81474 | G25: 425.38517 | H25: 446.60239 | I25: 467.441 | J25: 487.87268 | K25: 507.86562 | L25: 527.38375 | M25: 546.38586 | N25: 525.62183 | O25: 377.34179 | P25: 387.70067 | Q25: 397.80346 | R25: 407.38263 | S25: 416.21423 | T25: 400.28184 | U25: 383.13386 | V25: 364.45071 | W25: 343.77946 | X25: 320.41696 | Y25: 293.15278 | Z25: 259.58832 | AA25: 213.75722 | AB25: 131.85282
A26: Cash flow
A27: Receivables | B27: ₹ cr | D27: 148.3232 | E27: 147.95179 | F27: 147.58038 | G27: 147.20898 | H27: 146.83757 | I27: 146.46616 | J27: 146.09475 | K27: 145.72334 | L27: 145.35193 | M27: 144.98052 | N27: 144.60912 | O27: 144.23771 | P27: 143.8663 | Q27: 143.49489 | R27: 143.12348 | S27: 142.75207 | T27: 142.38066 | U27: 142.00926 | V27: 141.63785 | W27: 141.26644 | X27: 140.89503 | Y27: 140.52362 | Z27: 140.15221 | AA27: 139.7808 | AB27: 139.4094
A28: Working capital change | C28: 139.4094 | D28: 148.3232 | E28: -0.37140856 | F28: -0.37140856 | G28: -0.37140856 | H28: -0.37140856 | I28: -0.37140856 | J28: -0.37140856 | K28: -0.37140856 | L28: -0.37140856 | M28: -0.37140856 | N28: -0.37140856 | O28: -0.37140856 | P28: -0.37140856 | Q28: -0.37140856 | R28: -0.37140856 | S28: -0.37140856 | T28: -0.37140856 | U28: -0.37140856 | V28: -0.37140856 | W28: -0.37140856 | X28: -0.37140856 | Y28: -0.37140856 | Z28: -0.37140856 | AA28: -0.37140856 | AB28: -0.37140856
A29: Battery augmentation | C29: 1712.6509 | D29: 0 | E29: 71.360455 | F29: 71.360455 | G29: 71.360455 | H29: 71.360455 | I29: 71.360455 | J29: 71.360455 | K29: 71.360455 | L29: 71.360455 | M29: 71.360455 | N29: 71.360455 | O29: 71.360455 | P29: 71.360455 | Q29: 71.360455 | R29: 71.360455 | S29: 71.360455 | T29: 71.360455 | U29: 71.360455 | V29: 71.360455 | W29: 71.360455 | X29: 71.360455 | Y29: 71.360455 | Z29: 71.360455 | AA29: 71.360455 | AB29: 71.360455
A30: CFADS | C30: 20268.346 | D30: 960.99577 | E30: 1031.7117 | F30: 1024.9133 | G30: 1017.9255 | H30: 1010.739 | I30: 1003.3437 | J30: 995.72937 | K30: 987.88492 | L30: 979.79886 | M30: 971.45914 | N30: 923.65061 | O30: 748.66589 | P30: 732.71216 | Q30: 716.9598 | R30: 701.22442 | S30: 685.39021 | T30: 677.38675 | U30: 669.15883 | V30: 660.67004 | W30: 651.89219 | X30: 642.80178 | Y30: 633.37772 | Z30: 623.60007 | AA30: 613.4492 | AB30: 602.90525
A31: Debt service | C31: 9116.5338 | D31: 830.38195 | E31: 798.58009 | F31: 766.77823 | G31: 734.97637 | H31: 703.17451 | I31: 671.37264 | J31: 639.57078 | K31: 607.76892 | L31: 575.96706 | M31: 544.1652 | N31: 512.36333 | O31: 480.56147 | P31: 448.75961 | Q31: 416.95775 | R31: 385.15589 | S31: 1.330136e-13 | T31: 1.330136e-13 | U31: 1.330136e-13 | V31: 1.330136e-13 | W31: 1.330136e-13 | X31: 1.330136e-13 | Y31: 1.330136e-13 | Z31: 1.330136e-13 | AA31: 1.330136e-13 | AB31: 1.330136e-13
A32: Free cash to equity | C32: 12048.409 | D32: 130.61382 | E32: 233.13165 | F32: 258.13504 | G32: 282.94913 | H32: 307.56446 | I32: 331.97109 | J32: 356.15859 | K32: 380.116 | L32: 403.83181 | M32: 427.29394 | N32: 411.28727 | O32: 268.10441 | P32: 283.95255 | Q32: 300.00205 | R32: 316.06853 | S32: 685.39021 | T32: 677.38675 | U32: 669.15883 | V32: 660.67004 | W32: 651.89219 | X32: 642.80178 | Y32: 633.37772 | Z32: 623.60007 | AA32: 613.4492 | AB32: 1499.5018
A33: Cumulative equity cash | B33: ₹ cr | D33: -2140.9478 | E33: -1907.8161 | F33: -1649.6811 | G33: -1366.7319 | H33: -1059.1675 | I33: -727.19638 | J33: -371.03779 | K33: 9.0782044 | L33: 412.91001 | M33: 840.20395 | N33: 1251.4912 | O33: 1519.5956 | P33: 1803.5482 | Q33: 2103.5502 | R33: 2419.6188 | S33: 3105.009 | T33: 3782.3957 | U33: 4451.5546 | V33: 5112.2246 | W33: 5764.1168 | X33: 6406.9186 | Y33: 7040.2963 | Z33: 7663.8964 | AA33: 8277.3456 | AB33: 9776.8474
A34: Project cash flow | C34: 19524.145 | D34: 960.99577 | E34: 1031.7117 | F34: 1024.9133 | G34: 922.59206 | H34: 852.90041 | I34: 808.77817 | J34: 779.92732 | K34: 760.16549 | L34: 745.77961 | M34: 734.53794 | N34: 725.09737 | O34: 716.64777 | P34: 708.69858 | Q34: 700.95074 | R34: 693.21989 | S34: 685.39021 | T34: 677.38675 | U34: 669.15883 | V34: 660.67004 | W34: 651.89219 | X34: 642.80178 | Y34: 633.37772 | Z34: 623.60007 | AA34: 613.4492 | AB34: 1499.5018
A35: Debt
A36: Opening debt | B36: ₹ cr | D36: 5300.3103 | E36: 4946.9563 | F36: 4593.6023 | G36: 4240.2483 | H36: 3886.8943 | I36: 3533.5402 | J36: 3180.1862 | K36: 2826.8322 | L36: 2473.4782 | M36: 2120.1241 | N36: 1766.7701 | O36: 1413.4161 | P36: 1060.0621 | Q36: 706.70805 | R36: 353.35402 | S36: 1.4779289e-12 | T36: 1.4779289e-12 | U36: 1.4779289e-12 | V36: 1.4779289e-12 | W36: 1.4779289e-12 | X36: 1.4779289e-12 | Y36: 1.4779289e-12 | Z36: 1.4779289e-12 | AA36: 1.4779289e-12 | AB36: 1.4779289e-12
A37: Interest | C37: 3816.2235 | D37: 477.02793 | E37: 445.22607 | F37: 413.42421 | G37: 381.62235 | H37: 349.82048 | I37: 318.01862 | J37: 286.21676 | K37: 254.4149 | L37: 222.61303 | M37: 190.81117 | N37: 159.00931 | O37: 127.20745 | P37: 95.405586 | Q37: 63.603724 | R37: 31.801862 | S37: 1.330136e-13 | T37: 1.330136e-13 | U37: 1.330136e-13 | V37: 1.330136e-13 | W37: 1.330136e-13 | X37: 1.330136e-13 | Y37: 1.330136e-13 | Z37: 1.330136e-13 | AA37: 1.330136e-13 | AB37: 1.330136e-13
A38: Principal | C38: 5300.3103 | D38: 353.35402 | E38: 353.35402 | F38: 353.35402 | G38: 353.35402 | H38: 353.35402 | I38: 353.35402 | J38: 353.35402 | K38: 353.35402 | L38: 353.35402 | M38: 353.35402 | N38: 353.35402 | O38: 353.35402 | P38: 353.35402 | Q38: 353.35402 | R38: 353.35402 | S38: 0 | T38: 0 | U38: 0 | V38: 0 | W38: 0 | X38: 0 | Y38: 0 | Z38: 0 | AA38: 0 | AB38: 0
A39: Closing debt | B39: ₹ cr | D39: 4946.9563 | E39: 4593.6023 | F39: 4240.2483 | G39: 3886.8943 | H39: 3533.5402 | I39: 3180.1862 | J39: 2826.8322 | K39: 2473.4782 | L39: 2120.1241 | M39: 1766.7701 | N39: 1413.4161 | O39: 1060.0621 | P39: 706.70805 | Q39: 353.35402 | R39: 1.4779289e-12 | S39: 1.4779289e-12 | T39: 1.4779289e-12 | U39: 1.4779289e-12 | V39: 1.4779289e-12 | W39: 1.4779289e-12 | X39: 1.4779289e-12 | Y39: 1.4779289e-12 | Z39: 1.4779289e-12 | AA39: 1.4779289e-12 | AB39: 1.4779289e-12
A40: DSCR | B40: × | D40: 1.1572937 | E40: 1.2919327 | F40: 1.3366489 | G40: 1.3849772 | H40: 1.4373942 | I40: 1.4944662 | J40: 1.5568713 | K40: 1.6254285 | L40: 1.701137 | M40: 1.7852284 | N40: 1.8027258 | O40: 1.5578983 | P40: 1.6327498 | Q40: 1.7195023 | R40: 1.820625
...
